Workbook

Sheet Books (2026)
A1: Title | B1: Format | C1: Pages | D1: Remain | E1: Active | F1: =G1+1 -> 46387 | G1: =H1+1 -> 46386 | H1: =I1+1 -> 46385 | I1: =J1+1 -> 46384 | J1: =K1+1 -> 46383 | K1: =L1+1 -> 46382 | L1: =M1+1 -> 46381 | M1: =N1+1 -> 46380 | ... NE1: =NF1+1 -> 46024 | NF1: 46023
A2: books finished YTD | F2: {=IF(TODAY() >= F$1, SUM(N($C5:$C39=F5:F39)), "")} | G2: {=IF(TODAY() >= G$1, SUM(N($C5:$C39=G5:G39)), "")} | H2: {=IF(TODAY() >= H$1, SUM(N($C5:$C39=H5:H39)), "")} | I2: {=IF(TODAY() >= I$1, SUM(N($C5:$C39=I5:I39)), "")} | J2: {=IF(TODAY() >= J$1, SUM(N($C5:$C39=J5:J39)), "")} | K2: {=IF(TODAY() >= K$1, SUM(N($C5:$C39=K5:K39)), "")} | L2: {=IF(TODAY() >= L$1, SUM(N($C5:$C39=L5:L39)), "")} | M2: {=IF(TODAY() >= M$1, SUM(N($C5:$C39=M5:M39)), "")} | ... AI2: {=IF(TODAY() >= AI$1, SUM(N($C5:$C39=AI5:AI39)), "")} | AJ2: {=IF(TODAY() >= AJ$1, SUM(N($C6:$C39=AJ6:AJ39)), "")} | AK2: {=IF(TODAY() >= AK$1, SUM(N($C6:$C39=AK6:AK39)), "")} | AL2: {=IF(TODAY() >= AL$1, SUM(N($C6:$C39=AL6:AL39)), "")} | AM2: {=IF(TODAY() >= AM$1, SUM(N($C6:$C39=AM6:AM39)), "")} | AN2: {=IF(TODAY() >= AN$1, SUM(N($C6:$C39=AN6:AN39)), "")} | AO2: {=IF(TODAY() >= AO$1, SUM(N($C6:$C39=AO6:AO39)), "")} | AP2: {=IF(TODAY() >= AP$1, SUM(N($C6:$C39=AP6:AP39)), "")} | AQ2: {=IF(TODAY() >= AQ$1, SUM(N($C6:$C39=AQ6:AQ39)), "")} | ... NF2: {=IF(TODAY() >= NF$1, SUM(N($C6:$C39=NF6:NF39)), "")} -> 8
A3: pages read today | F3: =IF(TODAY() >= F$1, SUMIFS(F:F, $C:$C, "<>") - SUMIFS(#REF!, $C:$C, "<>") - 1, "") | G3: =IF(TODAY() >= G$1, SUMIFS(G:G, $C:$C, "<>") - SUMIFS(#REF!, $C:$C, "<>") - 1, "") | H3: =IF(TODAY() >= H$1, SUMIFS(H:H, $C:$C, "<>") - SUMIFS(#REF!, $C:$C, "<>") - 1, "") | I3: =IF(TODAY() >= I$1, SUMIFS(I:I, $C:$C, "<>") - SUMIFS(#REF!, $C:$C, "<>") - 1, "") | J3: =IF(TODAY() >= J$1, SUMIFS(J:J, $C:$C, "<>") - SUMIFS(#REF!, $C:$C, "<>") - 1, "") | K3: =IF(TODAY() >= K$1, SUMIFS(K:K, $C:$C, "<>") - SUMIFS(#REF!, $C:$C, "<>") - 1, "") | L3: =IF(TODAY() >= L$1, SUMIFS(L:L, $C:$C, "<>") - SUMIFS(#REF!, $C:$C, "<>") - 1, "") | M3: =IF(TODAY() >= M$1, SUMIFS(M:M, $C:$C, "<>") - SUMIFS(#REF!, $C:$C, "<>") - 1, "") | N3: =IF(TODAY() >= N$1, SUMIFS(N:N, $C:$C, "<>") - SUMIFS(#REF!, $C:$C, "<>") - 1, "") | O3: =IF(TODAY() >= O$1, SUMIFS(O:O, $C:$C, "<>") - SUMIFS(#REF!, $C:$C, "<>") - 1, "") | P3: =IF(TODAY() >= P$1, SUMIFS(P:P, $C:$C, "<>") - SUMIFS(#REF!, $C:$C, "<>") - 1, "") | Q3: =IF(TODAY() >= Q$1, SUMIFS(Q:Q, $C:$C, "<>") - SUMIFS(#REF!, $C:$C, "<>") - 1, "") | R3: =IF(TODAY() >= R$1, SUMIFS(R:R, $C:$C, "<>") - SUMIFS(#REF!, $C:$C, "<>") - 1, "") | S3: =IF(TODAY() >= S$1, SUMIFS(S:S, $C:$C, "<>") - SUMIFS(#REF!, $C:$C, "<>") - 1, "") | T3: =IF(TODAY() >= T$1, SUMIFS(T:T, $C:$C, "<>") - SUMIFS(#REF!, $C:$C, "<>") - 1, "") | U3: =IF(TODAY() >= U$1, SUMIFS(U:U, $C:$C, "<>") - SUMIFS(#REF!, $C:$C, "<>") - 1, "") | V3: =IF(TODAY() >= V$1, SUMIFS(V:V, $C:$C, "<>") - SUMIFS(#REF!, $C:$C, "<>") - 1, "") | W3: =IF(TODAY() >= W$1, SUMIFS(W:W, $C:$C, "<>") - SUMIFS(#REF!, $C:$C, "<>") - 1, "") | X3: =IF(TODAY() >= X$1, SUMIFS(X:X, $C:$C, "<>") - SUMIFS(#REF!, $C:$C, "<>") - 1, "") | Y3: =IF(TODAY() >= Y$1, SUMIFS(Y:Y, $C:$C, "<>") - SUMIFS(#REF!, $C:$C, "<>") - 1, "") | Z3: =IF(TODAY() >= Z$1, SUMIFS(Z:Z, $C:$C, "<>") - SUMIFS(#REF!, $C:$C, "<>") - 1, "") | AA3: =IF(TODAY() >= AA$1, SUMIFS(AA:AA, $C:$C, "<>") - SUMIFS(#REF!, $C:$C, "<>") - 1, "") | AB3: =IF(TODAY() >= AB$1, SUMIFS(AB:AB, $C:$C, "<>") - SUMIFS(#REF!, $C:$C, "<>") - 1, "") | AC3: =IF(TODAY() >= AC$1, SUMIFS(AC:AC, $C:$C, "<>") - SUMIFS(#REF!, $C:$C, "<>") - 1, "") | AD3: =IF(TODAY() >= AD$1, SUMIFS(AD:AD, $C:$C, "<>") - SUMIFS(#REF!, $C:$C, "<>") - 1, "") | AE3: =IF(TODAY() >= AE$1, SUMIFS(AE:AE, $C:$C, "<>") - SUMIFS(#REF!, $C:$C, "<>") - 1, "") | AF3: =IF(TODAY() >= AF$1, SUMIFS(AF:AF, $C:$C, "<>") - SUMIFS(#REF!, $C:$C, "<>") - 1, "") | AG3: =IF(TODAY() >= AG$1, SUMIFS(AG:AG, $C:$C, "<>") - SUMIFS(#REF!, $C:$C, "<>") - 1, "") | AH3: =IF(TODAY() >= AH$1, SUMIFS(AH:AH, $C:$C, "<>") - SUMIFS(#REF!, $C:$C, "<>") - 1, "") | AI3: =IF(TODAY() >= AI$1, SUMIFS(AI:AI, $C:$C, "<>") - SUMIFS(#REF!, $C:$C, "<>") - 1, "") | AJ3: =IF(TODAY() >= AJ$1, SUMIFS(AJ6:AJ39, $C6:$C39, "<>") - SUMIFS(AK6:AK39, $C6:$C39, "<>"), "") | AK3: =IF(TODAY() >= AK$1, SUMIFS(AK6:AK39, $C6:$C39, "<>") - SUMIFS(AL6:AL39, $C6:$C39, "<>"), "") | AL3: =IF(TODAY() >= AL$1, SUMIFS(AL6:AL39, $C6:$C39, "<>") - SUMIFS(AM6:AM39, $C6:$C39, "<>"), "") | AM3: =IF(TODAY() >= AM$1, SUMIFS(AM6:AM39, $C6:$C39, "<>") - SUMIFS(AN6:AN39, $C6:$C39, "<>"), "") | AN3: =IF(TODAY() >= AN$1, SUMIFS(AN6:AN39, $C6:$C39, "<>") - SUMIFS(AO6:AO39, $C6:$C39, "<>"), "") | AO3: =IF(TODAY() >= AO$1, SUMIFS(AO6:AO39, $C6:$C39, "<>") - SUMIFS(AP6:AP39, $C6:$C39, "<>"), "") | AP3: =IF(TODAY() >= AP$1, SUMIFS(AP6:AP39, $C6:$C39, "<>") - SUMIFS(AQ6:AQ39, $C6:$C39, "<>"), "") | AQ3: =IF(TODAY() >= AQ$1, SUMIFS(AQ6:AQ39, $C6:$C39, "<>") - SUMIFS(AR6:AR39, $C6:$C39, "<>"), "") | ... NE3: =IF(TODAY() >= NE$1, SUMIFS(NE6:NE39, $C6:$C39, "<>") - SUMIFS(NF6:NF39, $C6:$C39, "<>"), "") -> 0 | NF3: 0
A4: monthly pages read cumulative | F4: =IF(TODAY() >= F$1, SUMIFS(F3:NF3, F1:NF1, ">="&DATE(YEAR(F1), MONTH(F1), 1)), "") | G4: =IF(TODAY() >= G$1, SUMIFS(G3:NG3, G1:NG1, ">="&DATE(YEAR(G1), MONTH(G1), 1)), "") | H4: =IF(TODAY() >= H$1, SUMIFS(H3:NH3, H1:NH1, ">="&DATE(YEAR(H1), MONTH(H1), 1)), "") | I4: =IF(TODAY() >= I$1, SUMIFS(I3:NI3, I1:NI1, ">="&DATE(YEAR(I1), MONTH(I1), 1)), "") | J4: =IF(TODAY() >= J$1, SUMIFS(J3:NJ3, J1:NJ1, ">="&DATE(YEAR(J1), MONTH(J1), 1)), "") | K4: =IF(TODAY() >= K$1, SUMIFS(K3:NK3, K1:NK1, ">="&DATE(YEAR(K1), MONTH(K1), 1)), "") | L4: =IF(TODAY() >= L$1, SUMIFS(L3:NL3, L1:NL1, ">="&DATE(YEAR(L1), MONTH(L1), 1)), "") | M4: =IF(TODAY() >= M$1, SUMIFS(M3:NM3, M1:NM1, ">="&DATE(YEAR(M1), MONTH(M1), 1)), "") | ... AI4: =IF(TODAY() >= AI$1, SUMIFS(AI3:OI3, AI1:OI1, ">="&DATE(YEAR(AI1), MONTH(AI1), 1)), "") | AJ4: =IF(TODAY() >= AJ$1, AK4+AJ3, "") | AK4: =IF(TODAY() >= AK$1, AL4+AK3, "") | AL4: =IF(TODAY() >= AL$1, AM4+AL3, "") | AM4: =IF(TODAY() >= AM$1, AN4+AM3, "") | AN4: =IF(TODAY() >= AN$1, AO4+AN3, "") | AO4: =IF(TODAY() >= AO$1, AP4+AO3, "") | AP4: =IF(TODAY() >= AP$1, AQ4+AP3, "") | AQ4: =IF(TODAY() >= AQ$1, AR4+AQ3, "") | ... NE4: =IF(TODAY() >= NE$1, NF4+NE3, "") -> 0 | NF4: 0
A5: monthly goal | F5: =IF(TODAY() >= F1, (date(YEAR(F$1),MONTH(F$1)+1,1) - date(YEAR(F$1),MONTH(F$1),1)) * $B$57, "") | G5: =IF(TODAY() >= G1, (date(YEAR(G$1),MONTH(G$1)+1,1) - date(YEAR(G$1),MONTH(G$1),1)) * $B$57, "") | H5: =IF(TODAY() >= H1, (date(YEAR(H$1),MONTH(H$1)+1,1) - date(YEAR(H$1),MONTH(H$1),1)) * $B$57, "") | I5: =IF(TODAY() >= I1, (date(YEAR(I$1),MONTH(I$1)+1,1) - date(YEAR(I$1),MONTH(I$1),1)) * $B$57, "") | J5: =IF(TODAY() >= J1, (date(YEAR(J$1),MONTH(J$1)+1,1) - date(YEAR(J$1),MONTH(J$1),1)) * $B$57, "") | K5: =IF(TODAY() >= K1, (date(YEAR(K$1),MONTH(K$1)+1,1) - date(YEAR(K$1),MONTH(K$1),1)) * $B$57, "") | L5: =IF(TODAY() >= L1, (date(YEAR(L$1),MONTH(L$1)+1,1) - date(YEAR(L$1),MONTH(L$1),1)) * $B$57, "") | M5: =IF(TODAY() >= M1, (date(YEAR(M$1),MONTH(M$1)+1,1) - date(YEAR(M$1),MONTH(M$1),1)) * $B$57, "") | ... NF5: =IF(TODAY() >= NF1, (date(YEAR(NF$1),MONTH(NF$1)+1,1) - date(YEAR(NF$1),MONTH(NF$1),1)) * $B$57, "") -> 0
A6: The Happiness Trap | B6: Kindle | C6: 293 | D6: =C6 - MAX($F6:NF6) -> 222 | F6: =IF(TODAY() >= F$1, G6, "") | G6: =IF(TODAY() >= G$1, H6, "") | H6: =IF(TODAY() >= H$1, I6, "") | I6: =IF(TODAY() >= I$1, J6, "") | J6: =IF(TODAY() >= J$1, K6, "") | K6: =IF(TODAY() >= K$1, L6, "") | L6: =IF(TODAY() >= L$1, M6, "") | M6: =IF(TODAY() >= M$1, N6, "") | ... NE6: =IF(TODAY() >= NE$1, NF6, "") -> 71 | NF6: {=XLOOKUP(A6, 'Books (2025)'!A6:A39, 'Books (2025)'!F6:F39)} -> 71
A7: Getting Past Your Past | B7: Libby | C7: 352 | D7: =C7 - MAX($F7:NF7) -> 330.97101 | F7: =IF(TODAY() >= F$1, G7, "") | G7: =IF(TODAY() >= G$1, H7, "") | H7: =IF(TODAY() >= H$1, I7, "") | I7: =IF(TODAY() >= I$1, J7, "") | J7: =IF(TODAY() >= J$1, K7, "") | K7: =IF(TODAY() >= K$1, L7, "") | L7: =IF(TODAY() >= L$1, M7, "") | M7: =IF(TODAY() >= M$1, N7, "") | ... NE7: =IF(TODAY() >= NE$1, NF7, "") -> 21.028994 | NF7: {=XLOOKUP(A7, 'Books (2025)'!A7:A39, 'Books (2025)'!F7:F39)} -> 21.028994
A8: The Book of Why | B8: Kindle | C8: 419 | D8: =C8 - MAX($F8:NF8) -> 419 | F8: =IF(TODAY() >= F$1, G8, "") | G8: =IF(TODAY() >= G$1, H8, "") | H8: =IF(TODAY() >= H$1, I8, "") | I8: =IF(TODAY() >= I$1, J8, "") | J8: =IF(TODAY() >= J$1, K8, "") | K8: =IF(TODAY() >= K$1, L8, "") | L8: =IF(TODAY() >= L$1, M8, "") | M8: =IF(TODAY() >= M$1, N8, "") | ... NE8: =IF(TODAY() >= NE$1, NF8, "") -> 0 | NF8: {=XLOOKUP(A8, 'Books (2025)'!A8:A39, 'Books (2025)'!F8:F39)} -> 0
A9: Validation | C9: 414 | D9: =C9 - MAX($F9:NF9) -> 414 | F9: =IF(TODAY() >= F$1, G9, "") | G9: =IF(TODAY() >= G$1, H9, "") | H9: =IF(TODAY() >= H$1, I9, "") | I9: =IF(TODAY() >= I$1, J9, "") | J9: =IF(TODAY() >= J$1, K9, "") | K9: =IF(TODAY() >= K$1, L9, "") | L9: =IF(TODAY() >= L$1, M9, "") | M9: =IF(TODAY() >= M$1, N9, "") | ... NE9: =IF(TODAY() >= NE$1, NF9, "") -> 0 | NF9: {=XLOOKUP(A9, 'Books (2025)'!A9:A39, 'Books (2025)'!F9:F39)} -> 0
A10: The Real Happy Pill | C10: 414 | D10: =C10 - MAX($F10:NF10) -> 414 | F10: =IF(TODAY() >= F$1, G10, "") | G10: =IF(TODAY() >= G$1, H10, "") | H10: =IF(TODAY() >= H$1, I10, "") | I10: =IF(TODAY() >= I$1, J10, "") | J10: =IF(TODAY() >= J$1, K10, "") | K10: =IF(TODAY() >= K$1, L10, "") | L10: =IF(TODAY() >= L$1, M10, "") | M10: =IF(TODAY() >= M$1, N10, "") | ... NE10: =IF(TODAY() >= NE$1, NF10, "") -> 0 | NF10: {=XLOOKUP(A10, 'Books (2025)'!A10:A39, 'Books (2025)'!F10:F39)} -> 0
A11: The Body Keeps the Score | B11: Nook | C11: 414 | D11: =C11 - MAX($F11:NF11) -> 414 | F11: =IF(TODAY() >= F$1, G11, "") | G11: =IF(TODAY() >= G$1, H11, "") | H11: =IF(TODAY() >= H$1, I11, "") | I11: =IF(TODAY() >= I$1, J11, "") | J11: =IF(TODAY() >= J$1, K11, "") | K11: =IF(TODAY() >= K$1, L11, "") | L11: =IF(TODAY() >= L$1, M11, "") | M11: =IF(TODAY() >= M$1, N11, "") | ... NE11: =IF(TODAY() >= NE$1, NF11, "") -> 0 | NF11: {=XLOOKUP(A11, 'Books (2025)'!A11:A39, 'Books (2025)'!F11:F39)} -> 0
A12: Tapping In | C12: 414 | D12: =C12 - MAX($F12:NF12) -> 414 | F12: =IF(TODAY() >= F$1, G12, "") | G12: =IF(TODAY() >= G$1, H12, "") | H12: =IF(TODAY() >= H$1, I12, "") | I12: =IF(TODAY() >= I$1, J12, "") | J12: =IF(TODAY() >= J$1, K12, "") | K12: =IF(TODAY() >= K$1, L12, "") | L12: =IF(TODAY() >= L$1, M12, "") | M12: =IF(TODAY() >= M$1, N12, "") | ... NE12: =IF(TODAY() >= NE$1, NF12, "") -> 0 | NF12: {=XLOOKUP(A12, 'Books (2025)'!A12:A39, 'Books (2025)'!F12:F39)} -> 0
A13: Mrs. Dalloway | C13: 414 | D13: =C13 - MAX($F13:NF13) -> 414 | F13: =IF(TODAY() >= F$1, G13, "") | G13: =IF(TODAY() >= G$1, H13, "") | H13: =IF(TODAY() >= H$1, I13, "") | I13: =IF(TODAY() >= I$1, J13, "") | J13: =IF(TODAY() >= J$1, K13, "") | K13: =IF(TODAY() >= K$1, L13, "") | L13: =IF(TODAY() >= L$1, M13, "") | M13: =IF(TODAY() >= M$1, N13, "") | ... NE13: =IF(TODAY() >= NE$1, NF13, "") -> 0 | NF13: {=XLOOKUP(A13, 'Books (2025)'!A13:A39, 'Books (2025)'!F13:F39)} -> 0
A14: Hold Me Tight | B14: Libby | C14: 414 | D14: =C14 - MAX($F14:NF14) -> 414 | F14: =IF(TODAY() >= F$1, G14, "") | G14: =IF(TODAY() >= G$1, H14, "") | H14: =IF(TODAY() >= H$1, I14, "") | I14: =IF(TODAY() >= I$1, J14, "") | J14: =IF(TODAY() >= J$1, K14, "") | K14: =IF(TODAY() >= K$1, L14, "") | L14: =IF(TODAY() >= L$1, M14, "") | M14: =IF(TODAY() >= M$1, N14, "") | ... NE14: =IF(TODAY() >= NE$1, NF14, "") -> 0 | NF14: {=XLOOKUP(A14, 'Books (2025)'!A14:A39, 'Books (2025)'!F14:F39)} -> 0
A15: DBT Workbook for Narcissistic Abuse & Gaslighting | B15: Nook | C15: 414 | D15: =C15 - MAX($F15:NF15) -> 414 | F15: =IF(TODAY() >= F$1, G15, "") | G15: =IF(TODAY() >= G$1, H15, "") | H15: =IF(TODAY() >= H$1, I15, "") | I15: =IF(TODAY() >= I$1, J15, "") | J15: =IF(TODAY() >= J$1, K15, "") | K15: =IF(TODAY() >= K$1, L15, "") | L15: =IF(TODAY() >= L$1, M15, "") | M15: =IF(TODAY() >= M$1, N15, "") | ... NE15: =IF(TODAY() >= NE$1, NF15, "") -> 0 | NF15: {=XLOOKUP(A15, 'Books (2025)'!A15:A39, 'Books (2025)'!F15:F39)} -> 0
A16: CPTSD Workbook | B16: Kindle | C16: 414 | D16: =C16 - MAX($F16:NF16) -> 414 | F16: =IF(TODAY() >= F$1, G16, "") | G16: =IF(TODAY() >= G$1, H16, "") | H16: =IF(TODAY() >= H$1, I16, "") | I16: =IF(TODAY() >= I$1, J16, "") | J16: =IF(TODAY() >= J$1, K16, "") | K16: =IF(TODAY() >= K$1, L16, "") | L16: =IF(TODAY() >= L$1, M16, "") | M16: =IF(TODAY() >= M$1, N16, "") | ... NE16: =IF(TODAY() >= NE$1, NF16, "") -> 0 | NF16: {=XLOOKUP(A16, 'Books (2025)'!A16:A39, 'Books (2025)'!F16:F39)} -> 0
A17: It's Not You | B17: Libby | C17: 368 | D17: =C17 - MAX($F17:NF17) -> 368 | F17: =IF(TODAY() >= F$1, G17, "") | G17: =IF(TODAY() >= G$1, H17, "") | H17: =IF(TODAY() >= H$1, I17, "") | I17: =IF(TODAY() >= I$1, J17, "") | J17: =IF(TODAY() >= J$1, K17, "") | K17: =IF(TODAY() >= K$1, L17, "") | L17: =IF(TODAY() >= L$1, M17, "") | M17: =IF(TODAY() >= M$1, N17, "") | ... NE17: =IF(TODAY() >= NE$1, NF17, "") -> 0 | NF17: {=XLOOKUP(A17, 'Books (2025)'!A17:A39, 'Books (2025)'!F17:F39)} -> 0
A18: Complex PTSD | B18: Kindle | C18: 341 | D18: =C18 - MAX($F18:NF18) -> 339 | F18: =IF(TODAY() >= F$1, G18, "") | G18: =IF(TODAY() >= G$1, H18, "") | H18: =IF(TODAY() >= H$1, I18, "") | I18: =IF(TODAY() >= I$1, J18, "") | J18: =IF(TODAY() >= J$1, K18, "") | K18: =IF(TODAY() >= K$1, L18, "") | L18: =IF(TODAY() >= L$1, M18, "") | M18: =IF(TODAY() >= M$1, N18, "") | ... NE18: =IF(TODAY() >= NE$1, NF18, "") -> 2 | NF18: {=XLOOKUP(A18, 'Books (2025)'!A18:A39, 'Books (2025)'!F18:F39)} -> 2
A19: The (Mis)behavior of Markets | B19: Nook | C19: 307 | D19: =C19 - MAX($F19:NF19) -> 307 | F19: =IF(TODAY() >= F$1, G19, "") | G19: =IF(TODAY() >= G$1, H19, "") | H19: =IF(TODAY() >= H$1, I19, "") | I19: =IF(TODAY() >= I$1, J19, "") | J19: =IF(TODAY() >= J$1, K19, "") | K19: =IF(TODAY() >= K$1, L19, "") | L19: =IF(TODAY() >= L$1, M19, "") | M19: =IF(TODAY() >= M$1, N19, "") | ... NE19: =IF(TODAY() >= NE$1, NF19, "") -> 0 | NF19: {=XLOOKUP(A19, 'Books (2025)'!A19:A39, 'Books (2025)'!F19:F39)} -> 0
A20: What My Bones Know | B20: Libby | C20: 352 | D20: =C20 - MAX($F20:NF20) -> 305 | F20: =IF(TODAY() >= F$1, G20, "") | G20: =IF(TODAY() >= G$1, H20, "") | H20: =IF(TODAY() >= H$1, I20, "") | I20: =IF(TODAY() >= I$1, J20, "") | J20: =IF(TODAY() >= J$1, K20, "") | K20: =IF(TODAY() >= K$1, L20, "") | L20: =IF(TODAY() >= L$1, M20, "") | M20: =IF(TODAY() >= M$1, N20, "") | ... NE20: =IF(TODAY() >= NE$1, NF20, "") -> 47 | NF20: {=XLOOKUP(A20, 'Books (2025)'!A20:A39, 'Books (2025)'!F20:F39)} -> 47
A21: The Manager's Path | B21: Kindle | C21: 219 | D21: =C21 - MAX($F21:NF21) -> 219 | F21: =IF(TODAY() >= F$1, G21, "") | G21: =IF(TODAY() >= G$1, H21, "") | H21: =IF(TODAY() >= H$1, I21, "") | I21: =IF(TODAY() >= I$1, J21, "") | J21: =IF(TODAY() >= J$1, K21, "") | K21: =IF(TODAY() >= K$1, L21, "") | L21: =IF(TODAY() >= L$1, M21, "") | M21: =IF(TODAY() >= M$1, N21, "") | ... NE21: =IF(TODAY() >= NE$1, NF21, "") -> 0 | NF21: {=XLOOKUP(A21, 'Books (2025)'!A21:A39, 'Books (2025)'!F21:F39)} -> 0
A22: High Output Management | B22: Nook | C22: 215 | D22: =C22 - MAX($F22:NF22) -> 215 | F22: =IF(TODAY() >= F$1, G22, "") | G22: =IF(TODAY() >= G$1, H22, "") | H22: =IF(TODAY() >= H$1, I22, "") | I22: =IF(TODAY() >= I$1, J22, "") | J22: =IF(TODAY() >= J$1, K22, "") | K22: =IF(TODAY() >= K$1, L22, "") | L22: =IF(TODAY() >= L$1, M22, "") | M22: =IF(TODAY() >= M$1, N22, "") | ... NE22: =IF(TODAY() >= NE$1, NF22, "") -> 0 | NF22: {=XLOOKUP(A22, 'Books (2025)'!A22:A39, 'Books (2025)'!F22:F39)} -> 0
A23: Measure What Matters | B23: Nook | C23: 298 | D23: =C23 - MAX($F23:NF23) -> 204 | F23: =IF(TODAY() >= F$1, G23, "") | G23: =IF(TODAY() >= G$1, H23, "") | H23: =IF(TODAY() >= H$1, I23, "") | I23: =IF(TODAY() >= I$1, J23, "") | J23: =IF(TODAY() >= J$1, K23, "") | K23: =IF(TODAY() >= K$1, L23, "") | L23: =IF(TODAY() >= L$1, M23, "") | M23: =IF(TODAY() >= M$1, N23, "") | ... NE23: =IF(TODAY() >= NE$1, NF23, "") -> 94 | NF23: {=XLOOKUP(A23, 'Books (2025)'!A23:A39, 'Books (2025)'!F23:F39)} -> 94
A24: What I Wish I Knew When I was 20 | B24: physical | C24: 202 | D24: =C24 - MAX($F24:NF24) -> 202 | F24: =IF(TODAY() >= F$1, G24, "") | G24: =IF(TODAY() >= G$1, H24, "") | H24: =IF(TODAY() >= H$1, I24, "") | I24: =IF(TODAY() >= I$1, J24, "") | J24: =IF(TODAY() >= J$1, K24, "") | K24: =IF(TODAY() >= K$1, L24, "") | L24: =IF(TODAY() >= L$1, M24, "") | M24: =IF(TODAY() >= M$1, N24, "") | ... NE24: =IF(TODAY() >= NE$1, NF24, "") -> 0 | NF24: {=XLOOKUP(A24, 'Books (2025)'!A24:A39, 'Books (2025)'!F24:F39)} -> 0
A25: Getting the Love You Want | B25: Nook | C25: 298 | D25: =C25 - MAX($F25:NF25) -> 163 | F25: =IF(TODAY() >= F$1, G25, "") | G25: =IF(TODAY() >= G$1, H25, "") | H25: =IF(TODAY() >= H$1, I25, "") | I25: =IF(TODAY() >= I$1, J25, "") | J25: =IF(TODAY() >= J$1, K25, "") | K25: =IF(TODAY() >= K$1, L25, "") | L25: =IF(TODAY() >= L$1, M25, "") | M25: =IF(TODAY() >= M$1, N25, "") | ... NE25: =IF(TODAY() >= NE$1, NF25, "") -> 135 | NF25: {=XLOOKUP(A25, 'Books (2025)'!A25:A39, 'Books (2025)'!F25:F39)} -> 135
A26: How to Do the Work | B26: Nook | C26: 274 | D26: =C26 - MAX($F26:NF26) -> 135 | F26: =IF(TODAY() >= F$1, G26, "") | G26: =IF(TODAY() >= G$1, H26, "") | H26: =IF(TODAY() >= H$1, I26, "") | I26: =IF(TODAY() >= I$1, J26, "") | J26: =IF(TODAY() >= J$1, K26, "") | K26: =IF(TODAY() >= K$1, L26, "") | L26: =IF(TODAY() >= L$1, M26, "") | M26: =IF(TODAY() >= M$1, N26, "") | ... NE26: =IF(TODAY() >= NE$1, NF26, "") -> 139 | NF26: {=XLOOKUP(A26, 'Books (2025)'!A26:A39, 'Books (2025)'!F26:F39)} -> 139
A27: The Seven Principles for Making Marriage Work | B27: Nook | C27: 272 | D27: =C27 - MAX($F27:NF27) -> 123 | F27: =IF(TODAY() >= F$1, G27, "") | G27: =IF(TODAY() >= G$1, H27, "") | H27: =IF(TODAY() >= H$1, I27, "") | I27: =IF(TODAY() >= I$1, J27, "") | J27: =IF(TODAY() >= J$1, K27, "") | K27: =IF(TODAY() >= K$1, L27, "") | L27: =IF(TODAY() >= L$1, M27, "") | M27: =IF(TODAY() >= M$1, N27, "") | ... NE27: =IF(TODAY() >= NE$1, NF27, "") -> 149 | NF27: {=XLOOKUP(A27, 'Books (2025)'!A27:A39, 'Books (2025)'!F27:F39)} -> 149
A28: The DBT Workbook for Narcissistic Abuse and Gaslighting | B28: Nook | C28: 95 | D28: =C28 - MAX($F28:NF28) -> 95 | F28: =IF(TODAY() >= F$1, G28, "") | G28: =IF(TODAY() >= G$1, H28, "") | H28: =IF(TODAY() >= H$1, I28, "") | I28: =IF(TODAY() >= I$1, J28, "") | J28: =IF(TODAY() >= J$1, K28, "") | K28: =IF(TODAY() >= K$1, L28, "") | L28: =IF(TODAY() >= L$1, M28, "") | M28: =IF(TODAY() >= M$1, N28, "") | ... NE28: =IF(TODAY() >= NE$1, NF28, "") -> 0 | NF28: {=XLOOKUP(A28, 'Books (2025)'!A28:A39, 'Books (2025)'!F28:F39)} -> 0
A29: How to Be the Love You Seek | B29: Nook | C29: 261 | D29: =C29 - MAX($F29:NF29) -> 86 | F29: =IF(TODAY() >= F$1, G29, "") | G29: =IF(TODAY() >= G$1, H29, "") | H29: =IF(TODAY() >= H$1, I29, "") | I29: =IF(TODAY() >= I$1, J29, "") | J29: =IF(TODAY() >= J$1, K29, "") | K29: =IF(TODAY() >= K$1, L29, "") | L29: =IF(TODAY() >= L$1, M29, "") | M29: =IF(TODAY() >= M$1, N29, "") | ... NE29: =IF(TODAY() >= NE$1, NF29, "") -> 175 | NF29: {=XLOOKUP(A29, 'Books (2025)'!A29:A39, 'Books (2025)'!F29:F39)} -> 175
A30: Your Somatic Therapy Toolbox | B30: Kindle | C30: 153 | D30: =C30 - MAX($F30:NF30) -> 153 | F30: =IF(TODAY() >= F$1, G30, "") | G30: =IF(TODAY() >= G$1, H30, "") | H30: =IF(TODAY() >= H$1, I30, "") | I30: =IF(TODAY() >= I$1, J30, "") | J30: =IF(TODAY() >= J$1, K30, "") | K30: =IF(TODAY() >= K$1, L30, "") | L30: =IF(TODAY() >= L$1, M30, "") | M30: =IF(TODAY() >= M$1, N30, "") | ... NE30: =IF(TODAY() >= NE$1, NF30, "") -> 0 | NF30: {=XLOOKUP(A30, 'Books (2025)'!A30:A39, 'Books (2025)'!F30:F39)} -> 0
A31: Notes on Being a Man | B31: Nook | C31: 282 | D31: =C31 - MAX($F31:NF31) -> 159 | F31: =IF(TODAY() >= F$1, G31, "") | G31: =IF(TODAY() >= G$1, H31, "") | H31: =IF(TODAY() >= H$1, I31, "") | I31: =IF(TODAY() >= I$1, J31, "") | J31: =IF(TODAY() >= J$1, K31, "") | K31: =IF(TODAY() >= K$1, L31, "") | L31: =IF(TODAY() >= L$1, M31, "") | M31: =IF(TODAY() >= M$1, N31, "") | ... NE31: =IF(TODAY() >= NE$1, NF31, "") -> 123 | NF31: {=XLOOKUP(A31, 'Books (2025)'!A31:A39, 'Books (2025)'!F31:F39)} -> 123
A32: Scattered Minds
A33: Taking Charge of Adult ADHD
A34: The Gift of Imperfection, Brene Brown
A35: Everything is Tuberculosis, John Greene
A36: Cues: Master the Secret Language of Charismatic Communication
F37: =IF(TODAY() >= F$1, G37, "") | G37: =IF(TODAY() >= G$1, H37, "") | H37: =IF(TODAY() >= H$1, I37, "") | I37: =IF(TODAY() >= I$1, J37, "") | J37: =IF(TODAY() >= J$1, K37, "") | K37: =IF(TODAY() >= K$1, L37, "") | L37: =IF(TODAY() >= L$1, M37, "") | M37: =IF(TODAY() >= M$1, N37, "") | ... DX37: =IF(TODAY() >= DX$1, DY37, "")
A38: metadata
A39: daily reading goal (pages) | B39: 15

Sheet Books (2025)
A1: Title | B1: Format | C1: Pages | D1: Remain | E1: Active | F1: =G1+1 -> 46022 | G1: =H1+1 -> 46021 | H1: =I1+1 -> 46020 | I1: =J1+1 -> 46019 | J1: =K1+1 -> 46018 | K1: =L1+1 -> 46017 | L1: =M1+1 -> 46016 | M1: =N1+1 -> 46015 | ... MV1: =MW1+1 -> 45668 | MW1: 45667
A2: books finished YTD | F2: {=IF(TODAY() >= F$1, SUM(N($C6:$C52=F6:F52)), "")} -> 21 | G2: {=IF(TODAY() >= G$1, SUM(N($C6:$C52=G6:G52)), "")} -> 21 | H2: {=IF(TODAY() >= H$1, SUM(N($C6:$C52=H6:H52)), "")} -> 21 | I2: {=IF(TODAY() >= I$1, SUM(N($C6:$C52=I6:I52)), "")} -> 21 | J2: {=IF(TODAY() >= J$1, SUM(N($C6:$C52=J6:J52)), "")} -> 21 | K2: {=IF(TODAY() >= K$1, SUM(N($C6:$C52=K6:K52)), "")} -> 21 | L2: {=IF(TODAY() >= L$1, SUM(N($C6:$C52=L6:L52)), "")} -> 21 | M2: {=IF(TODAY() >= M$1, SUM(N($C6:$C52=M6:M52)), "")} -> 21 | ... MW2: {=IF(TODAY() >= MW$1, SUM(N($C6:$C52=MW6:MW52)), "")} -> 3
A3: pages read today | F3: =IF(TODAY() >= F$1, SUMIFS(F6:F52, $C6:$C52, "<>") - SUMIFS(G6:G52, $C6:$C52, "<>"), "") -> 0 | G3: =IF(TODAY() >= G$1, SUMIFS(G6:G52, $C6:$C52, "<>") - SUMIFS(H6:H52, $C6:$C52, "<>"), "") -> 0 | H3: =IF(TODAY() >= H$1, SUMIFS(H6:H52, $C6:$C52, "<>") - SUMIFS(I6:I52, $C6:$C52, "<>"), "") -> 123 | I3: =IF(TODAY() >= I$1, SUMIFS(I6:I52, $C6:$C52, "<>") - SUMIFS(J6:J52, $C6:$C52, "<>"), "") -> 0 | J3: =IF(TODAY() >= J$1, SUMIFS(J6:J52, $C6:$C52, "<>") - SUMIFS(K6:K52, $C6:$C52, "<>"), "") -> 0 | K3: =IF(TODAY() >= K$1, SUMIFS(K6:K52, $C6:$C52, "<>") - SUMIFS(L6:L52, $C6:$C52, "<>"), "") -> 0 | L3: =IF(TODAY() >= L$1, SUMIFS(L6:L52, $C6:$C52, "<>") - SUMIFS(M6:M52, $C6:$C52, "<>"), "") -> 0 | M3: =IF(TODAY() >= M$1, SUMIFS(M6:M52, $C6:$C52, "<>") - SUMIFS(N6:N52, $C6:$C52, "<>"), "") -> 0 | ... MV3: =IF(TODAY() >= MV$1, SUMIFS(MV6:MV52, $C6:$C52, "<>") - SUMIFS(MW6:MW52, $C6:$C52, "<>"), "") -> 0 | MW3: 0
A4: monthly pages read cumulative | F4: =G4+F3 -> 5364.029 | G4: =H4+G3 -> 5364.029 | H4: =I4+H3 -> 5364.029 | I4: =J4+I3 -> 5241.029 | J4: =K4+J3 -> 5241.029 | K4: =L4+K3 -> 5241.029 | L4: =M4+L3 -> 5241.029 | M4: =N4+M3 -> 5241.029 | ... MV4: =MW4+MV3 -> 0 | MW4: =IF(TODAY() >= MW$1, SUMIFS(MW3, MW1, ">="&DATE(YEAR(MW1), MONTH(MW1), 1)), "") -> 0
A5: monthly goal | F5: =IF(TODAY() >= F1, (date(YEAR(F$1),MONTH(F$1)+1,1) - date(YEAR(F$1),MONTH(F$1),1)) * $B$52, "") -> 465 | G5: =IF(TODAY() >= G1, (date(YEAR(G$1),MONTH(G$1)+1,1) - date(YEAR(G$1),MONTH(G$1),1)) * $B$52, "") -> 465 | H5: =IF(TODAY() >= H1, (date(YEAR(H$1),MONTH(H$1)+1,1) - date(YEAR(H$1),MONTH(H$1),1)) * $B$52, "") -> 465 | I5: =IF(TODAY() >= I1, (date(YEAR(I$1),MONTH(I$1)+1,1) - date(YEAR(I$1),MONTH(I$1),1)) * $B$52, "") -> 465 | J5: =IF(TODAY() >= J1, (date(YEAR(J$1),MONTH(J$1)+1,1) - date(YEAR(J$1),MONTH(J$1),1)) * $B$52, "") -> 465 | K5: =IF(TODAY() >= K1, (date(YEAR(K$1),MONTH(K$1)+1,1) - date(YEAR(K$1),MONTH(K$1),1)) * $B$52, "") -> 465 | L5: =IF(TODAY() >= L1, (date(YEAR(L$1),MONTH(L$1)+1,1) - date(YEAR(L$1),MONTH(L$1),1)) * $B$52, "") -> 465 | M5: =IF(TODAY() >= M1, (date(YEAR(M$1),MONTH(M$1)+1,1) - date(YEAR(M$1),MONTH(M$1),1)) * $B$52, "") -> 465 | ... MW5: =IF(TODAY() >= MW1, (date(YEAR(MW$1),MONTH(MW$1)+1,1) - date(YEAR(MW$1),MONTH(MW$1),1)) * $B$52, "") -> 465
A6: The Happiness Trap | B6: Kindle | C6: 293 | D6: =C6 - MAX($F6:MW6) -> 222 | E6: Y | F6: =IF(TODAY() >= F$1, G6, "") -> 71 | G6: =IF(TODAY() >= G$1, H6, "") -> 71 | H6: =IF(TODAY() >= H$1, I6, "") -> 71 | I6: =IF(TODAY() >= I$1, J6, "") -> 71 | J6: =IF(TODAY() >= J$1, K6, "") -> 71 | K6: =IF(TODAY() >= K$1, L6, "") -> 71 | L6: =IF(TODAY() >= L$1, M6, "") -> 71 | M6: =IF(TODAY() >= M$1, N6, "") -> 71 | ... DO6: =IF(TODAY() >= DO$1, DP6, "") -> 71 | DP6: 71 | DQ6: =IF(TODAY() >= DQ$1, DR6, "") -> 62 | DR6: =IF(TODAY() >= DR$1, DS6, "") -> 62 | DS6: =IF(TODAY() >= DS$1, DT6, "") -> 62 | DT6: =IF(TODAY() >= DT$1, DU6, "") -> 62 | DU6: =IF(TODAY() >= DU$1, DV6, "") -> 62 | DV6: =IF(TODAY() >= DV$1, DW6, "") -> 62 | DW6: =IF(TODAY() >= DW$1, DX6, "") -> 62 | DX6: =IF(TODAY() >= DX$1, DY6, "") -> 62 | ... GF6: =IF(TODAY() >= GF$1, GG6, "") -> 62 | GG6: =IF(TODAY() >= GG$1, HL6, "") -> 62 | GH6: =IF(TODAY() >= GH$1, GI6, "") -> 62 | GI6: =IF(TODAY() >= GI$1, GJ6, "") -> 62 | GJ6: =IF(TODAY() >= GJ$1, GK6, "") -> 62 | GK6: =IF(TODAY() >= GK$1, GL6, "") -> 62 | GL6: =IF(TODAY() >= GL$1, GM6, "") -> 62 | GM6: =IF(TODAY() >= GM$1, GN6, "") -> 62 | GN6: =IF(TODAY() >= GN$1, GO6, "") -> 62 | GO6: =IF(TODAY() >= GO$1, GP6, "") -> 62 | ... MD6: =IF(TODAY() >= MD$1, ME6, "") -> 62 | ME6: =MF6 -> 62 | MF6: =MG6 -> 62 | MG6: =MH6 -> 62 | MH6: =MI6 -> 62 | MI6: =MJ6 -> 62 | MJ6: =MK6 -> 62 | MK6: =ML6 -> 62 | ML6: =MM6 -> 62 | ... MU6: =MV6 -> 62 | MV6: 62 | MW6: 62
A7: Getting Past Your Past | B7: Libby | C7: 352 | D7: =C7 - MAX($F7:MW7) -> 330.97101 | E7: Y | F7: =IF(TODAY() >= F$1, G7, "") -> 21.028994 | G7: =IF(TODAY() >= G$1, H7, "") -> 21.028994 | H7: =IF(TODAY() >= H$1, I7, "") -> 21.028994 | I7: =IF(TODAY() >= I$1, J7, "") -> 21.028994 | J7: =IF(TODAY() >= J$1, K7, "") -> 21.028994 | K7: =IF(TODAY() >= K$1, L7, "") -> 21.028994 | L7: =IF(TODAY() >= L$1, M7, "") -> 21.028994 | M7: =IF(TODAY() >= M$1, N7, "") -> 21.028994 | ... EU7: =IF(TODAY() >= EU$1, EV7, "") -> 21.028994 | EV7: =(43+8/60)/(12*60+2)*$C7 -> 21.028994 | EW7: =IF(TODAY() >= EW$1, EX7, "") -> 0 | EX7: =IF(TODAY() >= EX$1, EY7, "") -> 0 | EY7: =IF(TODAY() >= EY$1, EZ7, "") -> 0 | EZ7: =IF(TODAY() >= EZ$1, FA7, "") -> 0 | FA7: =IF(TODAY() >= FA$1, FB7, "") -> 0 | FB7: =IF(TODAY() >= FB$1, FC7, "") -> 0 | FC7: =IF(TODAY() >= FC$1, FD7, "") -> 0 | FD7: =IF(TODAY() >= FD$1, FE7, "") -> 0 | ... GF7: =IF(TODAY() >= GF$1, GG7, "") -> 0 | GG7: 0 | GH7: =IF(TODAY() >= GH$1, GI7, "") | GI7: =IF(TODAY() >= GI$1, GJ7, "") | GJ7: =IF(TODAY() >= GJ$1, GK7, "") | GK7: =IF(TODAY() >= GK$1, GL7, "") | GL7: =IF(TODAY() >= GL$1, GM7, "") | GM7: =IF(TODAY() >= GM$1, GN7, "") | GN7: =IF(TODAY() >= GN$1, GO7, "") | GO7: =IF(TODAY() >= GO$1, GP7, "") | ... HK7: =IF(TODAY() >= HK$1, HL7, "")
A8: How to Avoid H.E.N.R.Y Syndrome | B8: Kindle | C8: 218 | D8: =C8 - MAX($F8:MW8) -> 0 | F8: =IF(TODAY() >= F$1, G8, "") -> 218 | G8: =IF(TODAY() >= G$1, H8, "") -> 218 | H8: =IF(TODAY() >= H$1, I8, "") -> 218 | I8: =IF(TODAY() >= I$1, J8, "") -> 218 | J8: =IF(TODAY() >= J$1, K8, "") -> 218 | K8: =IF(TODAY() >= K$1, L8, "") -> 218 | L8: =IF(TODAY() >= L$1, M8, "") -> 218 | M8: =IF(TODAY() >= M$1, N8, "") -> 218 | ... DZ8: =IF(TODAY() >= DZ$1, EA8, "") -> 218 | EA8: =ROUND(2007/2007*218,0) -> 218 | EB8: =IF(TODAY() >= EB$1, EC8, "") -> 105 | EC8: =IF(TODAY() >= EC$1, ED8, "") -> 105 | ED8: =IF(TODAY() >= ED$1, EE8, "") -> 105 | EE8: =IF(TODAY() >= EE$1, EF8, "") -> 105 | EF8: =IF(TODAY() >= EF$1, EG8, "") -> 105 | EG8: =IF(TODAY() >= EG$1, EH8, "") -> 105 | EH8: =IF(TODAY() >= EH$1, EI8, "") -> 105 | EI8: =IF(TODAY() >= EI$1, EJ8, "") -> 105 | EJ8: =ROUND(970/2007*218,0) -> 105 | EK8: =IF(TODAY() >= EK$1, EL8, "") -> 71 | EL8: =IF(TODAY() >= EL$1, EM8, "") -> 71 | EM8: =IF(TODAY() >= EM$1, EN8, "") -> 71 | EN8: =IF(TODAY() >= EN$1, EO8, "") -> 71 | EO8: =IF(TODAY() >= EO$1, EP8, "") -> 71 | EP8: =IF(TODAY() >= EP$1, EQ8, "") -> 71 | EQ8: =IF(TODAY() >= EQ$1, ER8, "") -> 71 | ER8: =IF(TODAY() >= ER$1, ES8, "") -> 71 | ... GF8: =IF(TODAY() >= GF$1, GG8, "") -> 71 | GG8: =IF(TODAY() >= GG$1, HL8, "") -> 71 | GH8: =IF(TODAY() >= GH$1, GI8, "") -> 71 | GI8: =IF(TODAY() >= GI$1, GJ8, "") -> 71 | GJ8: =IF(TODAY() >= GJ$1, GK8, "") -> 71 | GK8: =IF(TODAY() >= GK$1, GL8, "") -> 71 | GL8: =IF(TODAY() >= GL$1, GM8, "") -> 71 | GM8: =IF(TODAY() >= GM$1, GN8, "") -> 71 | GN8: =IF(TODAY() >= GN$1, GO8, "") -> 71 | GO8: =IF(TODAY() >= GO$1, GP8, "") -> 71 | ... LG8: =IF(TODAY() >= LG$1, LH8, "") -> 71 | LH8: =ROUND(653/2007*218,0) -> 71 | LI8: =IF(TODAY() >= LI$1, LJ8, "") -> 48 | LJ8: =IF(TODAY() >= LJ$1, LK8, "") -> 48 | LK8: =IF(TODAY() >= LK$1, LL8, "") -> 48 | LL8: =IF(TODAY() >= LL$1, LM8, "") -> 48 | LM8: =IF(TODAY() >= LM$1, LN8, "") -> 48 | LN8: =IF(TODAY() >= LN$1, LO8, "") -> 48 | LO8: =IF(TODAY() >= LO$1, LP8, "") -> 48 | LP8: =IF(TODAY() >= LP$1, LQ8, "") -> 48 | ... LZ8: =IF(TODAY() >= LZ$1, MA8, "") -> 48 | MA8: =ROUND(438/2007*218,0) -> 48 | MB8: =IF(TODAY() >= MB$1, MC8, "") -> 31 | MC8: =ROUND(282/2007*218,0) -> 31 | MD8: =IF(TODAY() >= MD$1, ME8, "") -> 0 | ME8: =MF8 -> 0 | MF8: =MG8 -> 0 | MG8: =MH8 -> 0 | MH8: =MI8 -> 0 | MI8: =MJ8 -> 0 | MJ8: =MK8 -> 0 | MK8: =ML8 -> 0 | ML8: =MM8 -> 0 | ... MU8: =MV8 -> 0 | MV8: 0 | MW8: 0
A9: The Book of Why | B9: Kindle | C9: 419 | D9: =C9 - MAX($F9:MW9) -> 419 | F9: =IF(TODAY() >= F$1, G9, "") -> 0 | G9: =IF(TODAY() >= G$1, H9, "") -> 0 | H9: =IF(TODAY() >= H$1, I9, "") -> 0 | I9: =IF(TODAY() >= I$1, J9, "") -> 0 | J9: =IF(TODAY() >= J$1, K9, "") -> 0 | K9: =IF(TODAY() >= K$1, L9, "") -> 0 | L9: =IF(TODAY() >= L$1, M9, "") -> 0 | M9: =IF(TODAY() >= M$1, N9, "") -> 0 | ... GF9: =IF(TODAY() >= GF$1, GG9, "") -> 0 | GG9: =IF(TODAY() >= GG$1, HL9, "") -> 0 | GH9: =IF(TODAY() >= GH$1, GI9, "") -> 0 | GI9: =IF(TODAY() >= GI$1, GJ9, "") -> 0 | GJ9: =IF(TODAY() >= GJ$1, GK9, "") -> 0 | GK9: =IF(TODAY() >= GK$1, GL9, "") -> 0 | GL9: =IF(TODAY() >= GL$1, GM9, "") -> 0 | GM9: =IF(TODAY() >= GM$1, GN9, "") -> 0 | GN9: =IF(TODAY() >= GN$1, GO9, "") -> 0 | GO9: =IF(TODAY() >= GO$1, GP9, "") -> 0 | ... MD9: =IF(TODAY() >= MD$1, ME9, "") -> 0 | ME9: =MF9 -> 0 | MF9: =MG9 -> 0 | MG9: =MH9 -> 0 | MH9: =MI9 -> 0 | MI9: =MJ9 -> 0 | MJ9: =MK9 -> 0 | MK9: =ML9 -> 0 | ML9: =MM9 -> 0 | ... MU9: =MV9 -> 0 | MV9: 0 | MW9: 0
A10: Validation | C10: 414 | D10: =C10 - MAX($F10:MW10) -> 414 | F10: =IF(TODAY() >= F$1, G10, "") -> 0 | G10: =IF(TODAY() >= G$1, H10, "") -> 0 | H10: =IF(TODAY() >= H$1, I10, "") -> 0 | I10: =IF(TODAY() >= I$1, J10, "") -> 0 | J10: =IF(TODAY() >= J$1, K10, "") -> 0 | K10: =IF(TODAY() >= K$1, L10, "") -> 0 | L10: =IF(TODAY() >= L$1, M10, "") -> 0 | M10: =IF(TODAY() >= M$1, N10, "") -> 0 | ... GF10: =IF(TODAY() >= GF$1, GG10, "") -> 0 | GG10: 0 | GH10: =IF(TODAY() >= GH$1, GI10, "") | GI10: =IF(TODAY() >= GI$1, GJ10, "") | GJ10: =IF(TODAY() >= GJ$1, GK10, "") | GK10: =IF(TODAY() >= GK$1, GL10, "") | GL10: =IF(TODAY() >= GL$1, GM10, "") | GM10: =IF(TODAY() >= GM$1, GN10, "") | GN10: =IF(TODAY() >= GN$1, GO10, "") | GO10: =IF(TODAY() >= GO$1, GP10, "") | ... HK10: =IF(TODAY() >= HK$1, HL10, "")
A11: The Real Happy Pill | C11: 414 | D11: =C11 - MAX($F11:MW11) -> 414 | F11: =IF(TODAY() >= F$1, G11, "") -> 0 | G11: =IF(TODAY() >= G$1, H11, "") -> 0 | H11: =IF(TODAY() >= H$1, I11, "") -> 0 | I11: =IF(TODAY() >= I$1, J11, "") -> 0 | J11: =IF(TODAY() >= J$1, K11, "") -> 0 | K11: =IF(TODAY() >= K$1, L11, "") -> 0 | L11: =IF(TODAY() >= L$1, M11, "") -> 0 | M11: =IF(TODAY() >= M$1, N11, "") -> 0 | ... GF11: =IF(TODAY() >= GF$1, GG11, "") -> 0 | GG11: =IF(TODAY() >= GG$1, HL11, "") -> 0 | GH11: =IF(TODAY() >= GH$1, GI11, "") -> 0 | GI11: =IF(TODAY() >= GI$1, GJ11, "") -> 0 | GJ11: =IF(TODAY() >= GJ$1, GK11, "") -> 0 | GK11: =IF(TODAY() >= GK$1, GL11, "") -> 0 | GL11: =IF(TODAY() >= GL$1, GM11, "") -> 0 | GM11: =IF(TODAY() >= GM$1, GN11, "") -> 0 | GN11: =IF(TODAY() >= GN$1, GO11, "") -> 0 | GO11: =IF(TODAY() >= GO$1, GP11, "") -> 0 | ... MD11: =IF(TODAY() >= MD$1, ME11, "") -> 0 | ME11: =MF11 -> 0 | MF11: =MG11 -> 0 | MG11: =MH11 -> 0 | MH11: =MI11 -> 0 | MI11: =MJ11 -> 0 | MJ11: =MK11 -> 0 | MK11: =ML11 -> 0 | ML11: =MM11 -> 0 | ... MU11: =MV11 -> 0 | MV11: 0 | MW11: 0
A12: The Body Keeps the Score | B12: Nook | C12: 414 | D12: =C12 - MAX($F12:MW12) -> 414 | F12: =IF(TODAY() >= F$1, G12, "") -> 0 | G12: =IF(TODAY() >= G$1, H12, "") -> 0 | H12: =IF(TODAY() >= H$1, I12, "") -> 0 | I12: =IF(TODAY() >= I$1, J12, "") -> 0 | J12: =IF(TODAY() >= J$1, K12, "") -> 0 | K12: =IF(TODAY() >= K$1, L12, "") -> 0 | L12: =IF(TODAY() >= L$1, M12, "") -> 0 | M12: =IF(TODAY() >= M$1, N12, "") -> 0 | ... GF12: =IF(TODAY() >= GF$1, GG12, "") -> 0 | GG12: =IF(TODAY() >= GG$1, HL12, "") -> 0 | GH12: =IF(TODAY() >= GH$1, GI12, "") -> 0 | GI12: =IF(TODAY() >= GI$1, GJ12, "") -> 0 | GJ12: =IF(TODAY() >= GJ$1, GK12, "") -> 0 | GK12: =IF(TODAY() >= GK$1, GL12, "") -> 0 | GL12: =IF(TODAY() >= GL$1, GM12, "") -> 0 | GM12: =IF(TODAY() >= GM$1, GN12, "") -> 0 | GN12: =IF(TODAY() >= GN$1, GO12, "") -> 0 | GO12: =IF(TODAY() >= GO$1, GP12, "") -> 0 | ... MD12: =IF(TODAY() >= MD$1, ME12, "") -> 0 | ME12: =MF12 -> 0 | MF12: =MG12 -> 0 | MG12: =MH12 -> 0 | MH12: =MI12 -> 0 | MI12: =MJ12 -> 0 | MJ12: =MK12 -> 0 | MK12: =ML12 -> 0 | ML12: =MM12 -> 0 | ... MU12: =MV12 -> 0 | MV12: 0 | MW12: 0
A13: Tapping In | C13: 414 | D13: =C13 - MAX($F13:MW13) -> 414 | F13: =IF(TODAY() >= F$1, G13, "") -> 0 | G13: =IF(TODAY() >= G$1, H13, "") -> 0 | H13: =IF(TODAY() >= H$1, I13, "") -> 0 | I13: =IF(TODAY() >= I$1, J13, "") -> 0 | J13: =IF(TODAY() >= J$1, K13, "") -> 0 | K13: =IF(TODAY() >= K$1, L13, "") -> 0 | L13: =IF(TODAY() >= L$1, M13, "") -> 0 | M13: =IF(TODAY() >= M$1, N13, "") -> 0 | ... GF13: =IF(TODAY() >= GF$1, GG13, "") -> 0 | GG13: 0 | GH13: =IF(TODAY() >= GH$1, GI13, "") | GI13: =IF(TODAY() >= GI$1, GJ13, "") | GJ13: =IF(TODAY() >= GJ$1, GK13, "") | GK13: =IF(TODAY() >= GK$1, GL13, "") | GL13: =IF(TODAY() >= GL$1, GM13, "") | GM13: =IF(TODAY() >= GM$1, GN13, "") | GN13: =IF(TODAY() >= GN$1, GO13, "") | GO13: =IF(TODAY() >= GO$1, GP13, "") | ... HK13: =IF(TODAY() >= HK$1, HL13, "")
A14: Mrs. Dalloway | C14: 414 | D14: =C14 - MAX($F14:MW14) -> 414 | F14: =IF(TODAY() >= F$1, G14, "") -> 0 | G14: =IF(TODAY() >= G$1, H14, "") -> 0 | H14: =IF(TODAY() >= H$1, I14, "") -> 0 | I14: =IF(TODAY() >= I$1, J14, "") -> 0 | J14: =IF(TODAY() >= J$1, K14, "") -> 0 | K14: =IF(TODAY() >= K$1, L14, "") -> 0 | L14: =IF(TODAY() >= L$1, M14, "") -> 0 | M14: =IF(TODAY() >= M$1, N14, "") -> 0 | ... GF14: =IF(TODAY() >= GF$1, GG14, "") -> 0 | GG14: 0 | GH14: =IF(TODAY() >= GH$1, GI14, "") | GI14: =IF(TODAY() >= GI$1, GJ14, "") | GJ14: =IF(TODAY() >= GJ$1, GK14, "") | GK14: =IF(TODAY() >= GK$1, GL14, "") | GL14: =IF(TODAY() >= GL$1, GM14, "") | GM14: =IF(TODAY() >= GM$1, GN14, "") | GN14: =IF(TODAY() >= GN$1, GO14, "") | GO14: =IF(TODAY() >= GO$1, GP14, "") | ... HK14: =IF(TODAY() >= HK$1, HL14, "")
A15: Hold Me Tight | B15: Libby | C15: 414 | D15: =C15 - MAX($F15:MW15) -> 414 | F15: =IF(TODAY() >= F$1, G15, "") -> 0 | G15: =IF(TODAY() >= G$1, H15, "") -> 0 | H15: =IF(TODAY() >= H$1, I15, "") -> 0 | I15: =IF(TODAY() >= I$1, J15, "") -> 0 | J15: =IF(TODAY() >= J$1, K15, "") -> 0 | K15: =IF(TODAY() >= K$1, L15, "") -> 0 | L15: =IF(TODAY() >= L$1, M15, "") -> 0 | M15: =IF(TODAY() >= M$1, N15, "") -> 0 | ... GF15: =IF(TODAY() >= GF$1, GG15, "") -> 0 | GG15: 0 | GH15: =IF(TODAY() >= GH$1, GI15, "") | GI15: =IF(TODAY() >= GI$1, GJ15, "") | GJ15: =IF(TODAY() >= GJ$1, GK15, "") | GK15: =IF(TODAY() >= GK$1, GL15, "") | GL15: =IF(TODAY() >= GL$1, GM15, "") | GM15: =IF(TODAY() >= GM$1, GN15, "") | GN15: =IF(TODAY() >= GN$1, GO15, "") | GO15: =IF(TODAY() >= GO$1, GP15, "") | ... HK15: =IF(TODAY() >= HK$1, HL15, "")
A16: DBT Workbook for Narcissistic Abuse & Gaslighting | B16: Nook | C16: 414 | D16: =C16 - MAX($F16:MW16) -> 414 | F16: =IF(TODAY() >= F$1, G16, "") -> 0 | G16: =IF(TODAY() >= G$1, H16, "") -> 0 | H16: =IF(TODAY() >= H$1, I16, "") -> 0 | I16: =IF(TODAY() >= I$1, J16, "") -> 0 | J16: =IF(TODAY() >= J$1, K16, "") -> 0 | K16: =IF(TODAY() >= K$1, L16, "") -> 0 | L16: =IF(TODAY() >= L$1, M16, "") -> 0 | M16: =IF(TODAY() >= M$1, N16, "") -> 0 | ... GF16: =IF(TODAY() >= GF$1, GG16, "") -> 0 | GG16: =IF(TODAY() >= GG$1, HL16, "") -> 0 | GH16: =IF(TODAY() >= GH$1, GI16, "") -> 0 | GI16: =IF(TODAY() >= GI$1, GJ16, "") -> 0 | GJ16: =IF(TODAY() >= GJ$1, GK16, "") -> 0 | GK16: =IF(TODAY() >= GK$1, GL16, "") -> 0 | GL16: =IF(TODAY() >= GL$1, GM16, "") -> 0 | GM16: =IF(TODAY() >= GM$1, GN16, "") -> 0 | GN16: =IF(TODAY() >= GN$1, GO16, "") -> 0 | GO16: =IF(TODAY() >= GO$1, GP16, "") -> 0 | ... MD16: =IF(TODAY() >= MD$1, ME16, "") -> 0 | ME16: =MF16 -> 0 | MF16: =MG16 -> 0 | MG16: =MH16 -> 0 | MH16: =MI16 -> 0 | MI16: =MJ16 -> 0 | MJ16: =MK16 -> 0 | MK16: =ML16 -> 0 | ML16: =MM16 -> 0 | ... MU16: =MV16 -> 0 | MV16: 0 | MW16: 0
A17: CPTSD Workbook | B17: Kindle | C17: 414 | D17: =C17 - MAX($F17:MW17) -> 414 | F17: =IF(TODAY() >= F$1, G17, "") -> 0 | G17: =IF(TODAY() >= G$1, H17, "") -> 0 | H17: =IF(TODAY() >= H$1, I17, "") -> 0 | I17: =IF(TODAY() >= I$1, J17, "") -> 0 | J17: =IF(TODAY() >= J$1, K17, "") -> 0 | K17: =IF(TODAY() >= K$1, L17, "") -> 0 | L17: =IF(TODAY() >= L$1, M17, "") -> 0 | M17: =IF(TODAY() >= M$1, N17, "") -> 0 | ... GF17: =IF(TODAY() >= GF$1, GG17, "") -> 0 | GG17: =IF(TODAY() >= GG$1, HL17, "") -> 0 | GH17: =IF(TODAY() >= GH$1, GI17, "") -> 0 | GI17: =IF(TODAY() >= GI$1, GJ17, "") -> 0 | GJ17: =IF(TODAY() >= GJ$1, GK17, "") -> 0 | GK17: =IF(TODAY() >= GK$1, GL17, "") -> 0 | GL17: =IF(TODAY() >= GL$1, GM17, "") -> 0 | GM17: =IF(TODAY() >= GM$1, GN17, "") -> 0 | GN17: =IF(TODAY() >= GN$1, GO17, "") -> 0 | GO17: =IF(TODAY() >= GO$1, GP17, "") -> 0 | ... MD17: =IF(TODAY() >= MD$1, ME17, "") -> 0 | ME17: =MF17 -> 0 | MF17: =MG17 -> 0 | MG17: =MH17 -> 0 | MH17: =MI17 -> 0 | MI17: =MJ17 -> 0 | MJ17: =MK17 -> 0 | MK17: =ML17 -> 0 | ML17: =MM17 -> 0 | ... MU17: =MV17 -> 0 | MV17: 0 | MW17: 0
A18: It's Not You | B18: Libby | C18: 368 | D18: =C18 - MAX($F18:MW18) -> 368 | F18: =IF(TODAY() >= F$1, G18, "") -> 0 | G18: =IF(TODAY() >= G$1, H18, "") -> 0 | H18: =IF(TODAY() >= H$1, I18, "") -> 0 | I18: =IF(TODAY() >= I$1, J18, "") -> 0 | J18: =IF(TODAY() >= J$1, K18, "") -> 0 | K18: =IF(TODAY() >= K$1, L18, "") -> 0 | L18: =IF(TODAY() >= L$1, M18, "") -> 0 | M18: =IF(TODAY() >= M$1, N18, "") -> 0 | ... GF18: =IF(TODAY() >= GF$1, GG18, "") -> 0 | GG18: =IF(TODAY() >= GG$1, HL18, "") -> 0 | GH18: =IF(TODAY() >= GH$1, GI18, "") -> 0 | GI18: =IF(TODAY() >= GI$1, GJ18, "") -> 0 | GJ18: =IF(TODAY() >= GJ$1, GK18, "") -> 0 | GK18: =IF(TODAY() >= GK$1, GL18, "") -> 0 | GL18: =IF(TODAY() >= GL$1, GM18, "") -> 0 | GM18: =IF(TODAY() >= GM$1, GN18, "") -> 0 | GN18: =IF(TODAY() >= GN$1, GO18, "") -> 0 | GO18: =IF(TODAY() >= GO$1, GP18, "") -> 0 | ... MV18: =IF(TODAY() >= MV$1, MW18, "") -> 0 | MW18: 0
A19: Complex PTSD | B19: Kindle | C19: 341 | D19: =C19 - MAX($F19:MW19) -> 339 | F19: =IF(TODAY() >= F$1, G19, "") -> 2 | G19: =IF(TODAY() >= G$1, H19, "") -> 2 | H19: =IF(TODAY() >= H$1, I19, "") -> 2 | I19: =IF(TODAY() >= I$1, J19, "") -> 2 | J19: =IF(TODAY() >= J$1, K19, "") -> 2 | K19: =IF(TODAY() >= K$1, L19, "") -> 2 | L19: =IF(TODAY() >= L$1, M19, "") -> 2 | M19: =IF(TODAY() >= M$1, N19, "") -> 2 | ... GF19: =IF(TODAY() >= GF$1, GG19, "") -> 2 | GG19: =IF(TODAY() >= GG$1, HL19, "") -> 2 | GH19: =IF(TODAY() >= GH$1, GI19, "") -> 2 | GI19: =IF(TODAY() >= GI$1, GJ19, "") -> 2 | GJ19: =IF(TODAY() >= GJ$1, GK19, "") -> 2 | GK19: =IF(TODAY() >= GK$1, GL19, "") -> 2 | GL19: =IF(TODAY() >= GL$1, GM19, "") -> 2 | GM19: =IF(TODAY() >= GM$1, GN19, "") -> 2 | GN19: =IF(TODAY() >= GN$1, GO19, "") -> 2 | GO19: =IF(TODAY() >= GO$1, GP19, "") -> 2 | ... JI19: =IF(TODAY() >= JI$1, JJ19, "") -> 2 | JJ19: 2 | JK19: =IF(TODAY() >= JK$1, JL19, "") -> 2 | JL19: =IF(TODAY() >= JL$1, JM19, "") -> 2 | JM19: =IF(TODAY() >= JM$1, JN19, "") -> 2 | JN19: =IF(TODAY() >= JN$1, JO19, "") -> 2 | JO19: =IF(TODAY() >= JO$1, JP19, "") -> 2 | JP19: =IF(TODAY() >= JP$1, JQ19, "") -> 2 | JQ19: =IF(TODAY() >= JQ$1, JR19, "") -> 2 | JR19: =IF(TODAY() >= JR$1, JS19, "") -> 2 | ... KN19: =IF(TODAY() >= KN$1, KO19, "") -> 2 | KO19: 2 | KP19: =IF(TODAY() >= KP$1, KQ19, "") -> 0 | KQ19: =IF(TODAY() >= KQ$1, KR19, "") -> 0 | KR19: =IF(TODAY() >= KR$1, KS19, "") -> 0 | KS19: =IF(TODAY() >= KS$1, KT19, "") -> 0 | KT19: =IF(TODAY() >= KT$1, KU19, "") -> 0 | KU19: =IF(TODAY() >= KU$1, KV19, "") -> 0 | KV19: =IF(TODAY() >= KV$1, KW19, "") -> 0 | KW19: =IF(TODAY() >= KW$1, KX19, "") -> 0 | ... MD19: =IF(TODAY() >= MD$1, ME19, "") -> 0 | ME19: =MF19 -> 0 | MF19: =MG19 -> 0 | MG19: =MH19 -> 0 | MH19: =MI19 -> 0 | MI19: =MJ19 -> 0 | MJ19: =MK19 -> 0 | MK19: =ML19 -> 0 | ML19: =MM19 -> 0 | ... MU19: =MV19 -> 0 | MV19: 0 | MW19: 0
A20: The (Mis)behavior of Markets | B20: Nook | C20: 307 | D20: =C20 - MAX($F20:MW20) -> 307 | F20: =IF(TODAY() >= F$1, G20, "") -> 0 | G20: =IF(TODAY() >= G$1, H20, "") -> 0 | H20: =IF(TODAY() >= H$1, I20, "") -> 0 | I20: =IF(TODAY() >= I$1, J20, "") -> 0 | J20: =IF(TODAY() >= J$1, K20, "") -> 0 | K20: =IF(TODAY() >= K$1, L20, "") -> 0 | L20: =IF(TODAY() >= L$1, M20, "") -> 0 | M20: =IF(TODAY() >= M$1, N20, "") -> 0 | ... GF20: =IF(TODAY() >= GF$1, GG20, "") -> 0 | GG20: =IF(TODAY() >= GG$1, HL20, "") -> 0 | GH20: =IF(TODAY() >= GH$1, GI20, "") -> 0 | GI20: =IF(TODAY() >= GI$1, GJ20, "") -> 0 | GJ20: =IF(TODAY() >= GJ$1, GK20, "") -> 0 | GK20: =IF(TODAY() >= GK$1, GL20, "") -> 0 | GL20: =IF(TODAY() >= GL$1, GM20, "") -> 0 | GM20: =IF(TODAY() >= GM$1, GN20, "") -> 0 | GN20: =IF(TODAY() >= GN$1, GO20, "") -> 0 | GO20: =IF(TODAY() >= GO$1, GP20, "") -> 0 | ... MD20: =IF(TODAY() >= MD$1, ME20, "") -> 0 | ME20: =MF20 -> 0 | MF20: =MG20 -> 0 | MG20: =MH20 -> 0 | MH20: =MI20 -> 0 | MI20: =MJ20 -> 0 | MJ20: =MK20 -> 0 | MK20: =ML20 -> 0 | ML20: =MM20 -> 0 | ... MU20: =MV20 -> 0 | MV20: 0 | MW20: 0
A21: What My Bones Know | B21: Libby | C21: 352 | D21: =C21 - MAX($F21:MW21) -> 305 | F21: =IF(TODAY() >= F$1, G21, "") -> 47 | G21: =IF(TODAY() >= G$1, H21, "") -> 47 | H21: =IF(TODAY() >= H$1, I21, "") -> 47 | I21: =IF(TODAY() >= I$1, J21, "") -> 47 | J21: =IF(TODAY() >= J$1, K21, "") -> 47 | K21: =IF(TODAY() >= K$1, L21, "") -> 47 | L21: =IF(TODAY() >= L$1, M21, "") -> 47 | M21: =IF(TODAY() >= M$1, N21, "") -> 47 | ... GF21: =IF(TODAY() >= GF$1, GG21, "") -> 47 | GG21: =IF(TODAY() >= GG$1, HL21, "") -> 47 | GH21: =IF(TODAY() >= GH$1, GI21, "") -> 47 | GI21: =IF(TODAY() >= GI$1, GJ21, "") -> 47 | GJ21: =IF(TODAY() >= GJ$1, GK21, "") -> 47 | GK21: =IF(TODAY() >= GK$1, GL21, "") -> 47 | GL21: =IF(TODAY() >= GL$1, GM21, "") -> 47 | GM21: =IF(TODAY() >= GM$1, GN21, "") -> 47 | GN21: =IF(TODAY() >= GN$1, GO21, "") -> 47 | GO21: =IF(TODAY() >= GO$1, GP21, "") -> 47 | ... MD21: =IF(TODAY() >= MD$1, ME21, "") -> 47 | ME21: 47 | MF21: =MG21 -> 0 | MG21: =MH21 -> 0 | MH21: =MI21 -> 0 | MI21: =MJ21 -> 0 | MJ21: 0 | MK21: =ML21 -> 0 | ML21: =MM21 -> 0 | MM21: =MN21 -> 0 | MN21: =MO21 -> 0 | MO21: =MP21 -> 0 | MP21: =MQ21 -> 0 | MQ21: =MR21 -> 0 | MR21: =MS21 -> 0 | ... MU21: =MV21 -> 0 | MV21: 0 | MW21: 0
A22: The Manager's Path | B22: Kindle | C22: 219 | D22: =C22 - MAX($F22:MW22) -> 219 | F22: =IF(TODAY() >= F$1, G22, "") -> 0 | G22: =IF(TODAY() >= G$1, H22, "") -> 0 | H22: =IF(TODAY() >= H$1, I22, "") -> 0 | I22: =IF(TODAY() >= I$1, J22, "") -> 0 | J22: =IF(TODAY() >= J$1, K22, "") -> 0 | K22: =IF(TODAY() >= K$1, L22, "") -> 0 | L22: =IF(TODAY() >= L$1, M22, "") -> 0 | M22: =IF(TODAY() >= M$1, N22, "") -> 0 | ... GF22: =IF(TODAY() >= GF$1, GG22, "") -> 0 | GG22: =IF(TODAY() >= GG$1, HL22, "") -> 0 | GH22: =IF(TODAY() >= GH$1, GI22, "") -> 0 | GI22: =IF(TODAY() >= GI$1, GJ22, "") -> 0 | GJ22: =IF(TODAY() >= GJ$1, GK22, "") -> 0 | GK22: =IF(TODAY() >= GK$1, GL22, "") -> 0 | GL22: =IF(TODAY() >= GL$1, GM22, "") -> 0 | GM22: =IF(TODAY() >= GM$1, GN22, "") -> 0 | GN22: =IF(TODAY() >= GN$1, GO22, "") -> 0 | GO22: =IF(TODAY() >= GO$1, GP22, "") -> 0 | ... MD22: =IF(TODAY() >= MD$1, ME22, "") -> 0 | ME22: =MF22 -> 0 | MF22: =MG22 -> 0 | MG22: =MH22 -> 0 | MH22: =MI22 -> 0 | MI22: =MJ22 -> 0 | MJ22: =MK22 -> 0 | MK22: =ML22 -> 0 | ML22: =MM22 -> 0 | ... MU22: =MV22 -> 0 | MV22: 0 | MW22: 0
A23: High Output Management | B23: Nook | C23: 215 | D23: =C23 - MAX($F23:MW23) -> 215 | F23: =IF(TODAY() >= F$1, G23, "") -> 0 | G23: =IF(TODAY() >= G$1, H23, "") -> 0 | H23: =IF(TODAY() >= H$1, I23, "") -> 0 | I23: =IF(TODAY() >= I$1, J23, "") -> 0 | J23: =IF(TODAY() >= J$1, K23, "") -> 0 | K23: =IF(TODAY() >= K$1, L23, "") -> 0 | L23: =IF(TODAY() >= L$1, M23, "") -> 0 | M23: =IF(TODAY() >= M$1, N23, "") -> 0 | ... GF23: =IF(TODAY() >= GF$1, GG23, "") -> 0 | GG23: =IF(TODAY() >= GG$1, HL23, "") -> 0 | GH23: =IF(TODAY() >= GH$1, GI23, "") -> 0 | GI23: =IF(TODAY() >= GI$1, GJ23, "") -> 0 | GJ23: =IF(TODAY() >= GJ$1, GK23, "") -> 0 | GK23: =IF(TODAY() >= GK$1, GL23, "") -> 0 | GL23: =IF(TODAY() >= GL$1, GM23, "") -> 0 | GM23: =IF(TODAY() >= GM$1, GN23, "") -> 0 | GN23: =IF(TODAY() >= GN$1, GO23, "") -> 0 | GO23: =IF(TODAY() >= GO$1, GP23, "") -> 0 | ... MD23: =IF(TODAY() >= MD$1, ME23, "") -> 0 | ME23: =MF23 -> 0 | MF23: =MG23 -> 0 | MG23: =MH23 -> 0 | MH23: =MI23 -> 0 | MI23: =MJ23 -> 0 | MJ23: =MK23 -> 0 | MK23: =ML23 -> 0 | ML23: =MM23 -> 0 | ... MU23: =MV23 -> 0 | MV23: 0 | MW23: 0
A24: Measure What Matters | B24: Nook | C24: 298 | D24: =C24 - MAX($F24:MW24) -> 204 | F24: =IF(TODAY() >= F$1, G24, "") -> 94 | G24: =IF(TODAY() >= G$1, H24, "") -> 94 | H24: =IF(TODAY() >= H$1, I24, "") -> 94 | I24: =IF(TODAY() >= I$1, J24, "") -> 94 | J24: =IF(TODAY() >= J$1, K24, "") -> 94 | K24: =IF(TODAY() >= K$1, L24, "") -> 94 | L24: =IF(TODAY() >= L$1, M24, "") -> 94 | M24: =IF(TODAY() >= M$1, N24, "") -> 94 | ... GF24: =IF(TODAY() >= GF$1, GG24, "") -> 94 | GG24: =IF(TODAY() >= GG$1, HL24, "") -> 94 | GH24: =IF(TODAY() >= GH$1, GI24, "") -> 94 | GI24: =IF(TODAY() >= GI$1, GJ24, "") -> 94 | GJ24: =IF(TODAY() >= GJ$1, GK24, "") -> 94 | GK24: =IF(TODAY() >= GK$1, GL24, "") -> 94 | GL24: =IF(TODAY() >= GL$1, GM24, "") -> 94 | GM24: =IF(TODAY() >= GM$1, GN24, "") -> 94 | GN24: =IF(TODAY() >= GN$1, GO24, "") -> 94 | GO24: =IF(TODAY() >= GO$1, GP24, "") -> 94 | ... MD24: =IF(TODAY() >= MD$1, ME24, "") -> 94 | ME24: =MF24 -> 94 | MF24: =MG24 -> 94 | MG24: =MH24 -> 94 | MH24: =MI24 -> 94 | MI24: =MJ24 -> 94 | MJ24: =MK24 -> 94 | MK24: =ML24 -> 94 | ML24: =MM24 -> 94 | ... MU24: =MV24 -> 94 | MV24: 94 | MW24: 94
A25: What I Wish I Knew When I was 20 | B25: physical | C25: 202 | D25: =C25 - MAX($F25:MW25) -> 202 | F25: =IF(TODAY() >= F$1, G25, "") -> 0 | G25: =IF(TODAY() >= G$1, H25, "") -> 0 | H25: =IF(TODAY() >= H$1, I25, "") -> 0 | I25: =IF(TODAY() >= I$1, J25, "") -> 0 | J25: =IF(TODAY() >= J$1, K25, "") -> 0 | K25: =IF(TODAY() >= K$1, L25, "") -> 0 | L25: =IF(TODAY() >= L$1, M25, "") -> 0 | M25: =IF(TODAY() >= M$1, N25, "") -> 0 | ... GF25: =IF(TODAY() >= GF$1, GG25, "") -> 0 | GG25: =IF(TODAY() >= GG$1, HL25, "") -> 0 | GH25: =IF(TODAY() >= GH$1, GI25, "") -> 0 | GI25: =IF(TODAY() >= GI$1, GJ25, "") -> 0 | GJ25: =IF(TODAY() >= GJ$1, GK25, "") -> 0 | GK25: =IF(TODAY() >= GK$1, GL25, "") -> 0 | GL25: =IF(TODAY() >= GL$1, GM25, "") -> 0 | GM25: =IF(TODAY() >= GM$1, GN25, "") -> 0 | GN25: =IF(TODAY() >= GN$1, GO25, "") -> 0 | GO25: =IF(TODAY() >= GO$1, GP25, "") -> 0 | ... MD25: =IF(TODAY() >= MD$1, ME25, "") -> 0 | ME25: =MF25 -> 0 | MF25: =MG25 -> 0 | MG25: =MH25 -> 0 | MH25: =MI25 -> 0 | MI25: =MJ25 -> 0 | MJ25: =MK25 -> 0 | MK25: =ML25 -> 0 | ML25: =MM25 -> 0 | ... MU25: =MV25 -> 0 | MV25: 0 | MW25: 0
A26: Getting the Love You Want | B26: Nook | C26: 298 | D26: =C26 - MAX($F26:MW26) -> 163 | F26: =IF(TODAY() >= F$1, G26, "") -> 135 | G26: =IF(TODAY() >= G$1, H26, "") -> 135 | H26: =IF(TODAY() >= H$1, I26, "") -> 135 | I26: =IF(TODAY() >= I$1, J26, "") -> 135 | J26: =IF(TODAY() >= J$1, K26, "") -> 135 | K26: =IF(TODAY() >= K$1, L26, "") -> 135 | L26: =IF(TODAY() >= L$1, M26, "") -> 135 | M26: =IF(TODAY() >= M$1, N26, "") -> 135 | ... GF26: =IF(TODAY() >= GF$1, GG26, "") -> 135 | GG26: =IF(TODAY() >= GG$1, HL26, "") -> 135 | GH26: =IF(TODAY() >= GH$1, GI26, "") -> 135 | GI26: =IF(TODAY() >= GI$1, GJ26, "") -> 135 | GJ26: =IF(TODAY() >= GJ$1, GK26, "") -> 135 | GK26: =IF(TODAY() >= GK$1, GL26, "") -> 135 | GL26: =IF(TODAY() >= GL$1, GM26, "") -> 135 | GM26: =IF(TODAY() >= GM$1, GN26, "") -> 135 | GN26: =IF(TODAY() >= GN$1, GO26, "") -> 135 | GO26: =IF(TODAY() >= GO$1, GP26, "") -> 135 | ... MD26: =IF(TODAY() >= MD$1, ME26, "") -> 135 | ME26: =MF26 -> 135 | MF26: =MG26 -> 135 | MG26: =MH26 -> 135 | MH26: =MI26 -> 135 | MI26: =MJ26 -> 135 | MJ26: =MK26 -> 135 | MK26: =ML26 -> 135 | ML26: =MM26 -> 135 | ... MU26: =MV26 -> 135 | MV26: 135 | MW26: 135
A27: How to Do the Work | B27: Nook | C27: 274 | D27: =C27 - MAX($F27:MW27) -> 135 | F27: =IF(TODAY() >= F$1, G27, "") -> 139 | G27: =IF(TODAY() >= G$1, H27, "") -> 139 | H27: =IF(TODAY() >= H$1, I27, "") -> 139 | I27: =IF(TODAY() >= I$1, J27, "") -> 139 | J27: =IF(TODAY() >= J$1, K27, "") -> 139 | K27: =IF(TODAY() >= K$1, L27, "") -> 139 | L27: =IF(TODAY() >= L$1, M27, "") -> 139 | M27: =IF(TODAY() >= M$1, N27, "") -> 139 | ... GF27: =IF(TODAY() >= GF$1, GG27, "") -> 139 | GG27: =IF(TODAY() >= GG$1, HL27, "") -> 139 | GH27: =IF(TODAY() >= GH$1, GI27, "") -> 139 | GI27: =IF(TODAY() >= GI$1, GJ27, "") -> 139 | GJ27: =IF(TODAY() >= GJ$1, GK27, "") -> 139 | GK27: =IF(TODAY() >= GK$1, GL27, "") -> 139 | GL27: =IF(TODAY() >= GL$1, GM27, "") -> 139 | GM27: =IF(TODAY() >= GM$1, GN27, "") -> 139 | GN27: =IF(TODAY() >= GN$1, GO27, "") -> 139 | GO27: =IF(TODAY() >= GO$1, GP27, "") -> 139 | ... MD27: =IF(TODAY() >= MD$1, ME27, "") -> 139 | ME27: =MF27 -> 139 | MF27: =MG27 -> 139 | MG27: =MH27 -> 139 | MH27: =MI27 -> 139 | MI27: =MJ27 -> 139 | MJ27: =MK27 -> 139 | MK27: =ML27 -> 139 | ML27: =MM27 -> 139 | ... MU27: =MV27 -> 139 | MV27: 139 | MW27: 139
A28: The Seven Principles for Making Marriage Work | B28: Nook | C28: 272 | D28: =C28 - MAX($F28:MW28) -> 123 | F28: =IF(TODAY() >= F$1, G28, "") -> 149 | G28: =IF(TODAY() >= G$1, H28, "") -> 149 | H28: =IF(TODAY() >= H$1, I28, "") -> 149 | I28: =IF(TODAY() >= I$1, J28, "") -> 149 | J28: =IF(TODAY() >= J$1, K28, "") -> 149 | K28: =IF(TODAY() >= K$1, L28, "") -> 149 | L28: =IF(TODAY() >= L$1, M28, "") -> 149 | M28: =IF(TODAY() >= M$1, N28, "") -> 149 | ... GF28: =IF(TODAY() >= GF$1, GG28, "") -> 149 | GG28: =IF(TODAY() >= GG$1, HL28, "") -> 149 | GH28: =IF(TODAY() >= GH$1, GI28, "") -> 149 | GI28: =IF(TODAY() >= GI$1, GJ28, "") -> 149 | GJ28: =IF(TODAY() >= GJ$1, GK28, "") -> 149 | GK28: =IF(TODAY() >= GK$1, GL28, "") -> 149 | GL28: =IF(TODAY() >= GL$1, GM28, "") -> 149 | GM28: =IF(TODAY() >= GM$1, GN28, "") -> 149 | GN28: =IF(TODAY() >= GN$1, GO28, "") -> 149 | GO28: =IF(TODAY() >= GO$1, GP28, "") -> 149 | ... MD28: =IF(TODAY() >= MD$1, ME28, "") -> 149 | ME28: =MF28 -> 149 | MF28: =MG28 -> 149 | MG28: =MH28 -> 149 | MH28: =MI28 -> 149 | MI28: =MJ28 -> 149 | MJ28: =MK28 -> 149 | MK28: =ML28 -> 149 | ML28: =MM28 -> 149 | ... MU28: =MV28 -> 149 | MV28: 149 | MW28: 149
A29: The DBT Workbook for Narcissistic Abuse and Gaslighting | B29: Nook | C29: 95 | D29: =C29 - MAX($F29:MW29) -> 95 | F29: =IF(TODAY() >= F$1, G29, "") -> 0 | G29: =IF(TODAY() >= G$1, H29, "") -> 0 | H29: =IF(TODAY() >= H$1, I29, "") -> 0 | I29: =IF(TODAY() >= I$1, J29, "") -> 0 | J29: =IF(TODAY() >= J$1, K29, "") -> 0 | K29: =IF(TODAY() >= K$1, L29, "") -> 0 | L29: =IF(TODAY() >= L$1, M29, "") -> 0 | M29: =IF(TODAY() >= M$1, N29, "") -> 0 | ... GF29: =IF(TODAY() >= GF$1, GG29, "") -> 0 | GG29: =IF(TODAY() >= GG$1, HL29, "") -> 0 | GH29: =IF(TODAY() >= GH$1, GI29, "") -> 0 | GI29: =IF(TODAY() >= GI$1, GJ29, "") -> 0 | GJ29: =IF(TODAY() >= GJ$1, GK29, "") -> 0 | GK29: =IF(TODAY() >= GK$1, GL29, "") -> 0 | GL29: =IF(TODAY() >= GL$1, GM29, "") -> 0 | GM29: =IF(TODAY() >= GM$1, GN29, "") -> 0 | GN29: =IF(TODAY() >= GN$1, GO29, "") -> 0 | GO29: =IF(TODAY() >= GO$1, GP29, "") -> 0 | ... MD29: =IF(TODAY() >= MD$1, ME29, "") -> 0 | ME29: =MF29 -> 0 | MF29: =MG29 -> 0 | MG29: =MH29 -> 0 | MH29: =MI29 -> 0 | MI29: =MJ29 -> 0 | MJ29: 0 | MK29: =ML29 -> 0 | ML29: =MM29 -> 0 | MM29: =MN29 -> 0 | MN29: =MO29 -> 0 | MO29: =MP29 -> 0 | MP29: =MQ29 -> 0 | MQ29: =MR29 -> 0 | MR29: =MS29 -> 0 | ... MU29: =MV29 -> 0 | MV29: 0 | MW29: 0
A30: How to Be the Love You Seek | B30: Nook | C30: 261 | D30: =C30 - MAX($F30:MW30) -> 86 | F30: =IF(TODAY() >= F$1, G30, "") -> 175 | G30: =IF(TODAY() >= G$1, H30, "") -> 175 | H30: =IF(TODAY() >= H$1, I30, "") -> 175 | I30: =IF(TODAY() >= I$1, J30, "") -> 175 | J30: =IF(TODAY() >= J$1, K30, "") -> 175 | K30: =IF(TODAY() >= K$1, L30, "") -> 175 | L30: =IF(TODAY() >= L$1, M30, "") -> 175 | M30: =IF(TODAY() >= M$1, N30, "") -> 175 | ... GF30: =IF(TODAY() >= GF$1, GG30, "") -> 175 | GG30: =IF(TODAY() >= GG$1, HL30, "") -> 175 | GH30: =IF(TODAY() >= GH$1, GI30, "") -> 175 | GI30: =IF(TODAY() >= GI$1, GJ30, "") -> 175 | GJ30: =IF(TODAY() >= GJ$1, GK30, "") -> 175 | GK30: =IF(TODAY() >= GK$1, GL30, "") -> 175 | GL30: =IF(TODAY() >= GL$1, GM30, "") -> 175 | GM30: =IF(TODAY() >= GM$1, GN30, "") -> 175 | GN30: =IF(TODAY() >= GN$1, GO30, "") -> 175 | GO30: =IF(TODAY() >= GO$1, GP30, "") -> 175 | ... MD30: =IF(TODAY() >= MD$1, ME30, "") -> 175 | ME30: =MF30 -> 175 | MF30: =MG30 -> 175 | MG30: =MH30 -> 175 | MH30: =MI30 -> 175 | MI30: =MJ30 -> 175 | MJ30: =MK30 -> 175 | MK30: =ML30 -> 175 | ML30: =MM30 -> 175 | ... MU30: =MV30 -> 175 | MV30: 175 | MW30: 175
A31: 天龍八部10: 生死無常 | B31: Libby | C31: 272 | D31: =C31 - MAX($F31:MW31) -> 0 | F31: =IF(TODAY() >= F$1, G31, "") -> 272 | G31: =IF(TODAY() >= G$1, H31, "") -> 272 | H31: =IF(TODAY() >= H$1, I31, "") -> 272 | I31: =IF(TODAY() >= I$1, J31, "") -> 272 | J31: =IF(TODAY() >= J$1, K31, "") -> 272 | K31: =IF(TODAY() >= K$1, L31, "") -> 272 | L31: =IF(TODAY() >= L$1, M31, "") -> 272 | M31: =IF(TODAY() >= M$1, N31, "") -> 272 | ... EI31: =IF(TODAY() >= EI$1, EJ31, "") -> 272 | EJ31: 272 | EK31: 0
A32: 天龍八部9: 會鬥少林 | B32: Libby | C32: 254 | D32: =C32 - MAX($F32:MW32) -> 0 | F32: =IF(TODAY() >= F$1, G32, "") -> 254 | G32: =IF(TODAY() >= G$1, H32, "") -> 254 | H32: =IF(TODAY() >= H$1, I32, "") -> 254 | I32: =IF(TODAY() >= I$1, J32, "") -> 254 | J32: =IF(TODAY() >= J$1, K32, "") -> 254 | K32: =IF(TODAY() >= K$1, L32, "") -> 254 | L32: =IF(TODAY() >= L$1, M32, "") -> 254 | M32: =IF(TODAY() >= M$1, N32, "") -> 254 | ... EJ32: =IF(TODAY() >= EJ$1, EK32, "") -> 254 | EK32: 254 | EL32: 0
A33: 天龍八部8: 小無相功 | B33: Libby | C33: 224 | D33: =C33 - MAX($F33:MW33) -> 0 | F33: =IF(TODAY() >= F$1, G33, "") -> 224 | G33: =IF(TODAY() >= G$1, H33, "") -> 224 | H33: =IF(TODAY() >= H$1, I33, "") -> 224 | I33: =IF(TODAY() >= I$1, J33, "") -> 224 | J33: =IF(TODAY() >= J$1, K33, "") -> 224 | K33: =IF(TODAY() >= K$1, L33, "") -> 224 | L33: =IF(TODAY() >= L$1, M33, "") -> 224 | M33: =IF(TODAY() >= M$1, N33, "") -> 224 | ... EK33: =IF(TODAY() >= EK$1, EL33, "") -> 224 | EL33: 224 | EM33: 0
A34: 天龍八部7: 天山童姥 | B34: Libby | C34: 216 | D34: =C34 - MAX($F34:MW34) -> 0 | F34: =IF(TODAY() >= F$1, G34, "") -> 216 | G34: =IF(TODAY() >= G$1, H34, "") -> 216 | H34: =IF(TODAY() >= H$1, I34, "") -> 216 | I34: =IF(TODAY() >= I$1, J34, "") -> 216 | J34: =IF(TODAY() >= J$1, K34, "") -> 216 | K34: =IF(TODAY() >= K$1, L34, "") -> 216 | L34: =IF(TODAY() >= L$1, M34, "") -> 216 | M34: =IF(TODAY() >= M$1, N34, "") -> 216 | ... EM34: =IF(TODAY() >= EM$1, EN34, "") -> 216 | EN34: 216
A35: 天龍八部6: 金戈鏖兵 | B35: Libby | C35: 275 | D35: =C35 - MAX($F35:MW35) -> 0 | F35: =IF(TODAY() >= F$1, G35, "") -> 275 | G35: =IF(TODAY() >= G$1, H35, "") -> 275 | H35: =IF(TODAY() >= H$1, I35, "") -> 275 | I35: =IF(TODAY() >= I$1, J35, "") -> 275 | J35: =IF(TODAY() >= J$1, K35, "") -> 275 | K35: =IF(TODAY() >= K$1, L35, "") -> 275 | L35: =IF(TODAY() >= L$1, M35, "") -> 275 | M35: =IF(TODAY() >= M$1, N35, "") -> 275 | ... EN35: =IF(TODAY() >= EN$1, EO35, "") -> 275 | EO35: 275 | EP35: 0
A36: 天龍八部5: 千里茫茫 | B36: Libby | C36: 275 | D36: =C36 - MAX($F36:MW36) -> 0 | F36: =IF(TODAY() >= F$1, G36, "") -> 275 | G36: =IF(TODAY() >= G$1, H36, "") -> 275 | H36: =IF(TODAY() >= H$1, I36, "") -> 275 | I36: =IF(TODAY() >= I$1, J36, "") -> 275 | J36: =IF(TODAY() >= J$1, K36, "") -> 275 | K36: =IF(TODAY() >= K$1, L36, "") -> 275 | L36: =IF(TODAY() >= L$1, M36, "") -> 275 | M36: =IF(TODAY() >= M$1, N36, "") -> 275 | ... EO36: =IF(TODAY() >= EO$1, EP36, "") -> 275 | EP36: 275 | EQ36: =IF(TODAY() >= EQ$1, ER36, "") -> 56 | ER36: 56
A37: 天龍八部4: 胡漢恩仇 | B37: Libby | C37: 240 | D37: =C37 - MAX($F37:MW37) -> 0 | F37: =IF(TODAY() >= F$1, G37, "") -> 240 | G37: =IF(TODAY() >= G$1, H37, "") -> 240 | H37: =IF(TODAY() >= H$1, I37, "") -> 240 | I37: =IF(TODAY() >= I$1, J37, "") -> 240 | J37: =IF(TODAY() >= J$1, K37, "") -> 240 | K37: =IF(TODAY() >= K$1, L37, "") -> 240 | L37: =IF(TODAY() >= L$1, M37, "") -> 240 | M37: =IF(TODAY() >= M$1, N37, "") -> 240 | ... EQ37: =IF(TODAY() >= EQ$1, ER37, "") -> 240 | ER37: 240 | ES37: =IF(TODAY() >= ES$1, ET37, "") -> 0 | ET37: =IF(TODAY() >= ET$1, EU37, "") -> 0 | EU37: 0
A38: 天龍八部3: 朱碧雙姝 | B38: Libby | C38: 235 | D38: =C38 - MAX($F38:MW38) -> 0 | F38: =IF(TODAY() >= F$1, G38, "") -> 235 | G38: =IF(TODAY() >= G$1, H38, "") -> 235 | H38: =IF(TODAY() >= H$1, I38, "") -> 235 | I38: =IF(TODAY() >= I$1, J38, "") -> 235 | J38: =IF(TODAY() >= J$1, K38, "") -> 235 | K38: =IF(TODAY() >= K$1, L38, "") -> 235 | L38: =IF(TODAY() >= L$1, M38, "") -> 235 | M38: =IF(TODAY() >= M$1, N38, "") -> 235 | ... ET38: =IF(TODAY() >= ET$1, EU38, "") -> 235 | EU38: 235 | EV38: =IF(TODAY() >= EV$1, EW38, "") -> 16 | EW38: =IF(TODAY() >= EW$1, EX38, "") -> 16 | EX38: =IF(TODAY() >= EX$1, EY38, "") -> 16 | EY38: 16
A39: 天龍八部2: 六脈神劍 | B39: Libby | C39: 235 | D39: =C39 - MAX($F39:MW39) -> 0 | F39: =IF(TODAY() >= F$1, G39, "") -> 235 | G39: =IF(TODAY() >= G$1, H39, "") -> 235 | H39: =IF(TODAY() >= H$1, I39, "") -> 235 | I39: =IF(TODAY() >= I$1, J39, "") -> 235 | J39: =IF(TODAY() >= J$1, K39, "") -> 235 | K39: =IF(TODAY() >= K$1, L39, "") -> 235 | L39: =IF(TODAY() >= L$1, M39, "") -> 235 | M39: =IF(TODAY() >= M$1, N39, "") -> 235 | ... EX39: =IF(TODAY() >= EX$1, EY39, "") -> 235 | EY39: 235 | EZ39: 188 | FA39: =IF(TODAY() >= FA$1, FB39, "") -> 86 | FB39: 86 | FC39: 0
A40: 天龍八部1: 無量玉壁 | B40: Libby | C40: 252 | D40: =C40 - MAX($F40:MW40) -> 0 | F40: =IF(TODAY() >= F$1, G40, "") -> 252 | G40: =IF(TODAY() >= G$1, H40, "") -> 252 | H40: =IF(TODAY() >= H$1, I40, "") -> 252 | I40: =IF(TODAY() >= I$1, J40, "") -> 252 | J40: =IF(TODAY() >= J$1, K40, "") -> 252 | K40: =IF(TODAY() >= K$1, L40, "") -> 252 | L40: =IF(TODAY() >= L$1, M40, "") -> 252 | M40: =IF(TODAY() >= M$1, N40, "") -> 252 | ... FB40: =IF(TODAY() >= FB$1, FC40, "") -> 252 | FC40: 252 | FD40: 109 | FE40: =IF(TODAY() >= FE$1, FF40, "") -> 0 | FF40: =IF(TODAY() >= FF$1, FG40, "") -> 0 | FG40: =IF(TODAY() >= FG$1, FH40, "") -> 0 | FH40: =IF(TODAY() >= FH$1, FI40, "") -> 0 | FI40: =IF(TODAY() >= FI$1, FJ40, "") -> 0 | FJ40: =IF(TODAY() >= FJ$1, FK40, "") -> 0 | FK40: =IF(TODAY() >= FK$1, FL40, "") -> 0 | FL40: =IF(TODAY() >= FL$1, FM40, "") -> 0 | ... GF40: =IF(TODAY() >= GF$1, GG40, "") -> 0 | GG40: 0 | GH40: =IF(TODAY() >= GH$1, GI40, "") | GI40: =IF(TODAY() >= GI$1, GJ40, "") | GJ40: =IF(TODAY() >= GJ$1, GK40, "") | GK40: =IF(TODAY() >= GK$1, GL40, "") | GL40: =IF(TODAY() >= GL$1, GM40, "") | GM40: =IF(TODAY() >= GM$1, GN40, "") | GN40: =IF(TODAY() >= GN$1, GO40, "") | GO40: =IF(TODAY() >= GO$1, GP40, "") | ... HK40: =IF(TODAY() >= HK$1, HL40, "")
...

Sheet LC
A1: Week | B1: Goal | C1: Resource Focus | D1: Unit | E1: NeetCode Video | F1: LeetCode | G1: GeeksForGeeks | H1: Date | I1: Progress
A2: 1 | B2: Master basic array manipulations, frequency counting, and hash map usage. | C2: NeetCode's "Arrays & Hasing" section | D2: 1 | E2: Valid Anagram, Contains Duplicate | F2: 217, 242 | G2: Basic Array operations, Hash Map introduction
D3: 2 | E3: Two Sum, Group Anagrams | F3: 1, 49 | G3: Two Pointer technique
D4: 3 | E4: Top K Frequent Elements, Product of Array Except Self | F4: 347, 238 | G4: Frequency counting using hash maps
